Workbook

Sheet Stage 1
A1: Stage 1 · Project Familiarisation & Initiation — desglose por entregable y empresa (AUD)
A2: Importe = horas × tarifa de venta (pestaña Datos). Reparto por empresa según el tipo de cada entregable (pestaña Escenarios).
B4: Reducción de precio del Stage 1 | C4: =Resumen!$C$5 -> 0 | D4: =Resumen!$C$6 -> IDOM | E4: Se cambian en el panel de control de la pestaña Resumen (porcentaje y quién la absorbe).
A6: Oferta original | F6: Reparto | J6: =Escenarios!I$10&" · "&Escenarios!I$11 -> Escenario 1 · Original | P6: =Escenarios!J$10&" · "&Escenarios!J$11 -> Escenario 2 · Sin las 4 tareas de Plan Safe | V6: =Escenarios!K$10&" · "&Escenarios!K$11 -> Escenario 3 · Sin tareas Plan Safe ni SSC | AB6: =Escenarios!L$10&" · "&Escenarios!L$11 -> Escenario 4 · Sin SSC, tareas Plan Safe al 50 %
A7: Código | B7: Entregable | C7: Tipo | D7: Horas base | E7: Importe base | F7: % IDOM | G7: % Plan Safe | H7: % Synertec | I7: % INVAP | J7: Horas | K7: IDOM | L7: Plan Safe | M7: Synertec | N7: INVAP | O7: Total | P7: Horas | Q7: IDOM | R7: Plan Safe | S7: Synertec | T7: INVAP | U7: Total | V7: Horas | W7: IDOM | X7: Plan Safe | Y7: Synertec | Z7: INVAP | AA7: Total | AB7: Horas | AC7: IDOM | AD7: Plan Safe | AE7: Synertec | AF7: INVAP | AG7: Total
A8: S1 | B8: Safety Assurance Plan / Safety Integration Plan | C8: =INDEX(Escenarios!$D$12:$D$36,MATCH($A8,Escenarios!$A$12:$A$36,0)) -> Compartido | D8: =SUMIFS(Datos!$H$5:$H$291,Datos!$E$5:$E$291,$A8,Datos!$F$5:$F$291,"S1") -> 625 | E8: =SUMIFS(Datos!$J$5:$J$291,Datos!$E$5:$E$291,$A8,Datos!$F$5:$F$291,"S1") -> 148179.67 | F8: =INDEX(Escenarios!$E$12:$E$36,MATCH($A8,Escenarios!$A$12:$A$36,0)) -> 0.9 | G8: =INDEX(Escenarios!$F$12:$F$36,MATCH($A8,Escenarios!$A$12:$A$36,0)) -> 0.1 | H8: =INDEX(Escenarios!$G$12:$G$36,MATCH($A8,Escenarios!$A$12:$A$36,0)) -> 0 | I8: =INDEX(Escenarios!$H$12:$H$36,MATCH($A8,Escenarios!$A$12:$A$36,0)) -> 0 | J8: =IF(INDEX(Escenarios!$I$12:$I$36,MATCH($A8,Escenarios!$A$12:$A$36,0))>0,$D8,0) -> 625 | K8: =$E8*INDEX(Escenarios!$I$12:$I$36,MATCH($A8,Escenarios!$A$12:$A$36,0))*F8 -> 133361.71 | L8: =$E8*INDEX(Escenarios!$I$12:$I$36,MATCH($A8,Escenarios!$A$12:$A$36,0))*G8 -> 14817.968 | M8: =$E8*INDEX(Escenarios!$I$12:$I$36,MATCH($A8,Escenarios!$A$12:$A$36,0))*H8 -> 0 | N8: =$E8*INDEX(Escenarios!$I$12:$I$36,MATCH($A8,Escenarios!$A$12:$A$36,0))*I8 -> 0 | O8: =SUM(K8:N8) -> 148179.67 | P8: =IF(INDEX(Escenarios!$J$12:$J$36,MATCH($A8,Escenarios!$A$12:$A$36,0))>0,$D8,0) -> 625 | Q8: =$E8*INDEX(Escenarios!$J$12:$J$36,MATCH($A8,Escenarios!$A$12:$A$36,0))*F8 -> 133361.71 | R8: =$E8*INDEX(Escenarios!$J$12:$J$36,MATCH($A8,Escenarios!$A$12:$A$36,0))*G8 -> 14817.968 | S8: =$E8*INDEX(Escenarios!$J$12:$J$36,MATCH($A8,Escenarios!$A$12:$A$36,0))*H8 -> 0 | T8: =$E8*INDEX(Escenarios!$J$12:$J$36,MATCH($A8,Escenarios!$A$12:$A$36,0))*I8 -> 0 | U8: =SUM(Q8:T8) -> 148179.67 | V8: =IF(INDEX(Escenarios!$K$12:$K$36,MATCH($A8,Escenarios!$A$12:$A$36,0))>0,$D8,0) -> 625 | W8: =$E8*INDEX(Escenarios!$K$12:$K$36,MATCH($A8,Escenarios!$A$12:$A$36,0))*F8 -> 133361.71 | X8: =$E8*INDEX(Escenarios!$K$12:$K$36,MATCH($A8,Escenarios!$A$12:$A$36,0))*G8 -> 14817.968 | Y8: =$E8*INDEX(Escenarios!$K$12:$K$36,MATCH($A8,Escenarios!$A$12:$A$36,0))*H8 -> 0 | Z8: =$E8*INDEX(Escenarios!$K$12:$K$36,MATCH($A8,Escenarios!$A$12:$A$36,0))*I8 -> 0 | AA8: =SUM(W8:Z8) -> 148179.67 | AB8: =IF(INDEX(Escenarios!$L$12:$L$36,MATCH($A8,Escenarios!$A$12:$A$36,0))>0,$D8,0) -> 625 | AC8: =$E8*INDEX(Escenarios!$L$12:$L$36,MATCH($A8,Escenarios!$A$12:$A$36,0))*F8 -> 133361.71 | AD8: =$E8*INDEX(Escenarios!$L$12:$L$36,MATCH($A8,Escenarios!$A$12:$A$36,0))*G8 -> 14817.968 | AE8: =$E8*INDEX(Escenarios!$L$12:$L$36,MATCH($A8,Escenarios!$A$12:$A$36,0))*H8 -> 0 | AF8: =$E8*INDEX(Escenarios!$L$12:$L$36,MATCH($A8,Escenarios!$A$12:$A$36,0))*I8 -> 0 | AG8: =SUM(AC8:AF8) -> 148179.67
A9: Pre | B9: Conceptual Design Verification | C9: =INDEX(Escenarios!$D$12:$D$36,MATCH($A9,Escenarios!$A$12:$A$36,0)) -> INVAP | D9: =SUMIFS(Datos!$H$5:$H$291,Datos!$E$5:$E$291,$A9,Datos!$F$5:$F$291,"S1") -> 345 | E9: =SUMIFS(Datos!$J$5:$J$291,Datos!$E$5:$E$291,$A9,Datos!$F$5:$F$291,"S1") -> 78836.1 | F9: =INDEX(Escenarios!$E$12:$E$36,MATCH($A9,Escenarios!$A$12:$A$36,0)) -> 0 | G9: =INDEX(Escenarios!$F$12:$F$36,MATCH($A9,Escenarios!$A$12:$A$36,0)) -> 0 | H9: =INDEX(Escenarios!$G$12:$G$36,MATCH($A9,Escenarios!$A$12:$A$36,0)) -> 0 | I9: =INDEX(Escenarios!$H$12:$H$36,MATCH($A9,Escenarios!$A$12:$A$36,0)) -> 1 | J9: =IF(INDEX(Escenarios!$I$12:$I$36,MATCH($A9,Escenarios!$A$12:$A$36,0))>0,$D9,0) -> 345 | K9: =$E9*INDEX(Escenarios!$I$12:$I$36,MATCH($A9,Escenarios!$A$12:$A$36,0))*F9 -> 0 | L9: =$E9*INDEX(Escenarios!$I$12:$I$36,MATCH($A9,Escenarios!$A$12:$A$36,0))*G9 -> 0 | M9: =$E9*INDEX(Escenarios!$I$12:$I$36,MATCH($A9,Escenarios!$A$12:$A$36,0))*H9 -> 0 | N9: =$E9*INDEX(Escenarios!$I$12:$I$36,MATCH($A9,Escenarios!$A$12:$A$36,0))*I9 -> 78836.1 | O9: =SUM(K9:N9) -> 78836.1 | P9: =IF(INDEX(Escenarios!$J$12:$J$36,MATCH($A9,Escenarios!$A$12:$A$36,0))>0,$D9,0) -> 345 | Q9: =$E9*INDEX(Escenarios!$J$12:$J$36,MATCH($A9,Escenarios!$A$12:$A$36,0))*F9 -> 0 | R9: =$E9*INDEX(Escenarios!$J$12:$J$36,MATCH($A9,Escenarios!$A$12:$A$36,0))*G9 -> 0 | S9: =$E9*INDEX(Escenarios!$J$12:$J$36,MATCH($A9,Escenarios!$A$12:$A$36,0))*H9 -> 0 | T9: =$E9*INDEX(Escenarios!$J$12:$J$36,MATCH($A9,Escenarios!$A$12:$A$36,0))*I9 -> 78836.1 | U9: =SUM(Q9:T9) -> 78836.1 | V9: =IF(INDEX(Escenarios!$K$12:$K$36,MATCH($A9,Escenarios!$A$12:$A$36,0))>0,$D9,0) -> 345 | W9: =$E9*INDEX(Escenarios!$K$12:$K$36,MATCH($A9,Escenarios!$A$12:$A$36,0))*F9 -> 0 | X9: =$E9*INDEX(Escenarios!$K$12:$K$36,MATCH($A9,Escenarios!$A$12:$A$36,0))*G9 -> 0 | Y9: =$E9*INDEX(Escenarios!$K$12:$K$36,MATCH($A9,Escenarios!$A$12:$A$36,0))*H9 -> 0 | Z9: =$E9*INDEX(Escenarios!$K$12:$K$36,MATCH($A9,Escenarios!$A$12:$A$36,0))*I9 -> 78836.1 | AA9: =SUM(W9:Z9) -> 78836.1 | AB9: =IF(INDEX(Escenarios!$L$12:$L$36,MATCH($A9,Escenarios!$A$12:$A$36,0))>0,$D9,0) -> 345 | AC9: =$E9*INDEX(Escenarios!$L$12:$L$36,MATCH($A9,Escenarios!$A$12:$A$36,0))*F9 -> 0 | AD9: =$E9*INDEX(Escenarios!$L$12:$L$36,MATCH($A9,Escenarios!$A$12:$A$36,0))*G9 -> 0 | AE9: =$E9*INDEX(Escenarios!$L$12:$L$36,MATCH($A9,Escenarios!$A$12:$A$36,0))*H9 -> 0 | AF9: =$E9*INDEX(Escenarios!$L$12:$L$36,MATCH($A9,Escenarios!$A$12:$A$36,0))*I9 -> 78836.1 | AG9: =SUM(AC9:AF9) -> 78836.1
A10: S2 | B10: Human Factors Assurance Plan / Human Factors Integration Plan (HFIP) | C10: =INDEX(Escenarios!$D$12:$D$36,MATCH($A10,Escenarios!$A$12:$A$36,0)) -> Plan Safe | D10: =SUMIFS(Datos!$H$5:$H$291,Datos!$E$5:$E$291,$A10,Datos!$F$5:$F$291,"S1") -> 270 | E10: =SUMIFS(Datos!$J$5:$J$291,Datos!$E$5:$E$291,$A10,Datos!$F$5:$F$291,"S1") -> 62875.575 | F10: =INDEX(Escenarios!$E$12:$E$36,MATCH($A10,Escenarios!$A$12:$A$36,0)) -> 0 | G10: =INDEX(Escenarios!$F$12:$F$36,MATCH($A10,Escenarios!$A$12:$A$36,0)) -> 1 | H10: =INDEX(Escenarios!$G$12:$G$36,MATCH($A10,Escenarios!$A$12:$A$36,0)) -> 0 | I10: =INDEX(Escenarios!$H$12:$H$36,MATCH($A10,Escenarios!$A$12:$A$36,0)) -> 0 | J10: =IF(INDEX(Escenarios!$I$12:$I$36,MATCH($A10,Escenarios!$A$12:$A$36,0))>0,$D10,0) -> 270 | K10: =$E10*INDEX(Escenarios!$I$12:$I$36,MATCH($A10,Escenarios!$A$12:$A$36,0))*F10 -> 0 | L10: =$E10*INDEX(Escenarios!$I$12:$I$36,MATCH($A10,Escenarios!$A$12:$A$36,0))*G10 -> 62875.575 | M10: =$E10*INDEX(Escenarios!$I$12:$I$36,MATCH($A10,Escenarios!$A$12:$A$36,0))*H10 -> 0 | N10: =$E10*INDEX(Escenarios!$I$12:$I$36,MATCH($A10,Escenarios!$A$12:$A$36,0))*I10 -> 0 | O10: =SUM(K10:N10) -> 62875.575 | P10: =IF(INDEX(Escenarios!$J$12:$J$36,MATCH($A10,Escenarios!$A$12:$A$36,0))>0,$D10,0) -> 0 | Q10: =$E10*INDEX(Escenarios!$J$12:$J$36,MATCH($A10,Escenarios!$A$12:$A$36,0))*F10 -> 0 | R10: =$E10*INDEX(Escenarios!$J$12:$J$36,MATCH($A10,Escenarios!$A$12:$A$36,0))*G10 -> 0 | S10: =$E10*INDEX(Escenarios!$J$12:$J$36,MATCH($A10,Escenarios!$A$12:$A$36,0))*H10 -> 0 | T10: =$E10*INDEX(Escenarios!$J$12:$J$36,MATCH($A10,Escenarios!$A$12:$A$36,0))*I10 -> 0 | U10: =SUM(Q10:T10) -> 0 | V10: =IF(INDEX(Escenarios!$K$12:$K$36,MATCH($A10,Escenarios!$A$12:$A$36,0))>0,$D10,0) -> 0 | W10: =$E10*INDEX(Escenarios!$K$12:$K$36,MATCH($A10,Escenarios!$A$12:$A$36,0))*F10 -> 0 | X10: =$E10*INDEX(Escenarios!$K$12:$K$36,MATCH($A10,Escenarios!$A$12:$A$36,0))*G10 -> 0 | Y10: =$E10*INDEX(Escenarios!$K$12:$K$36,MATCH($A10,Escenarios!$A$12:$A$36,0))*H10 -> 0 | Z10: =$E10*INDEX(Escenarios!$K$12:$K$36,MATCH($A10,Escenarios!$A$12:$A$36,0))*I10 -> 0 | AA10: =SUM(W10:Z10) -> 0 | AB10: =IF(INDEX(Escenarios!$L$12:$L$36,MATCH($A10,Escenarios!$A$12:$A$36,0))>0,$D10,0) -> 270 | AC10: =$E10*INDEX(Escenarios!$L$12:$L$36,MATCH($A10,Escenarios!$A$12:$A$36,0))*F10 -> 0 | AD10: =$E10*INDEX(Escenarios!$L$12:$L$36,MATCH($A10,Escenarios!$A$12:$A$36,0))*G10 -> 31437.787 | AE10: =$E10*INDEX(Escenarios!$L$12:$L$36,MATCH($A10,Escenarios!$A$12:$A$36,0))*H10 -> 0 | AF10: =$E10*INDEX(Escenarios!$L$12:$L$36,MATCH($A10,Escenarios!$A$12:$A$36,0))*I10 -> 0 | AG10: =SUM(AC10:AF10) -> 31437.787
A11: S3 | B11: Human Factors Hazards Identification and Control Plan (HFHICP) | C11: =INDEX(Escenarios!$D$12:$D$36,MATCH($A11,Escenarios!$A$12:$A$36,0)) -> Plan Safe | D11: =SUMIFS(Datos!$H$5:$H$291,Datos!$E$5:$E$291,$A11,Datos!$F$5:$F$291,"S1") -> 195 | E11: =SUMIFS(Datos!$J$5:$J$291,Datos!$E$5:$E$291,$A11,Datos!$F$5:$F$291,"S1") -> 45191.475 | F11: =INDEX(Escenarios!$E$12:$E$36,MATCH($A11,Escenarios!$A$12:$A$36,0)) -> 0 | G11: =INDEX(Escenarios!$F$12:$F$36,MATCH($A11,Escenarios!$A$12:$A$36,0)) -> 1 | H11: =INDEX(Escenarios!$G$12:$G$36,MATCH($A11,Escenarios!$A$12:$A$36,0)) -> 0 | I11: =INDEX(Escenarios!$H$12:$H$36,MATCH($A11,Escenarios!$A$12:$A$36,0)) -> 0 | J11: =IF(INDEX(Escenarios!$I$12:$I$36,MATCH($A11,Escenarios!$A$12:$A$36,0))>0,$D11,0) -> 195 | K11: =$E11*INDEX(Escenarios!$I$12:$I$36,MATCH($A11,Escenarios!$A$12:$A$36,0))*F11 -> 0 | L11: =$E11*INDEX(Escenarios!$I$12:$I$36,MATCH($A11,Escenarios!$A$12:$A$36,0))*G11 -> 45191.475 | M11: =$E11*INDEX(Escenarios!$I$12:$I$36,MATCH($A11,Escenarios!$A$12:$A$36,0))*H11 -> 0 | N11: =$E11*INDEX(Escenarios!$I$12:$I$36,MATCH($A11,Escenarios!$A$12:$A$36,0))*I11 -> 0 | O11: =SUM(K11:N11) -> 45191.475 | P11: =IF(INDEX(Escenarios!$J$12:$J$36,MATCH($A11,Escenarios!$A$12:$A$36,0))>0,$D11,0) -> 0 | Q11: =$E11*INDEX(Escenarios!$J$12:$J$36,MATCH($A11,Escenarios!$A$12:$A$36,0))*F11 -> 0 | R11: =$E11*INDEX(Escenarios!$J$12:$J$36,MATCH($A11,Escenarios!$A$12:$A$36,0))*G11 -> 0 | S11: =$E11*INDEX(Escenarios!$J$12:$J$36,MATCH($A11,Escenarios!$A$12:$A$36,0))*H11 -> 0 | T11: =$E11*INDEX(Escenarios!$J$12:$J$36,MATCH($A11,Escenarios!$A$12:$A$36,0))*I11 -> 0 | U11: =SUM(Q11:T11) -> 0 | V11: =IF(INDEX(Escenarios!$K$12:$K$36,MATCH($A11,Escenarios!$A$12:$A$36,0))>0,$D11,0) -> 0 | W11: =$E11*INDEX(Escenarios!$K$12:$K$36,MATCH($A11,Escenarios!$A$12:$A$36,0))*F11 -> 0 | X11: =$E11*INDEX(Escenarios!$K$12:$K$36,MATCH($A11,Escenarios!$A$12:$A$36,0))*G11 -> 0 | Y11: =$E11*INDEX(Escenarios!$K$12:$K$36,MATCH($A11,Escenarios!$A$12:$A$36,0))*H11 -> 0 | Z11: =$E11*INDEX(Escenarios!$K$12:$K$36,MATCH($A11,Escenarios!$A$12:$A$36,0))*I11 -> 0 | AA11: =SUM(W11:Z11) -> 0 | AB11: =IF(INDEX(Escenarios!$L$12:$L$36,MATCH($A11,Escenarios!$A$12:$A$36,0))>0,$D11,0) -> 195 | AC11: =$E11*INDEX(Escenarios!$L$12:$L$36,MATCH($A11,Escenarios!$A$12:$A$36,0))*F11 -> 0 | AD11: =$E11*INDEX(Escenarios!$L$12:$L$36,MATCH($A11,Escenarios!$A$12:$A$36,0))*G11 -> 22595.737 | AE11: =$E11*INDEX(Escenarios!$L$12:$L$36,MATCH($A11,Escenarios!$A$12:$A$36,0))*H11 -> 0 | AF11: =$E11*INDEX(Escenarios!$L$12:$L$36,MATCH($A11,Escenarios!$A$12:$A$36,0))*I11 -> 0 | AG11: =SUM(AC11:AF11) -> 22595.737
B12: Subtotal Stage 1 (entregables) | D12: =SUM(D8:D11) -> 1435 | E12: =SUM(E8:E11) -> 335082.83 | J12: =SUM(J8:J11) -> 1435 | K12: =SUM(K8:K11) -> 133361.71 | L12: =SUM(L8:L11) -> 122885.02 | M12: =SUM(M8:M11) -> 0 | N12: =SUM(N8:N11) -> 78836.1 | O12: =SUM(O8:O11) -> 335082.83 | P12: =SUM(P8:P11) -> 970 | Q12: =SUM(Q8:Q11) -> 133361.71 | ... AG12: =SUM(AG8:AG11) -> 281049.3
B13: ="Reducción de precio del Stage 1 ("&TEXT(Resumen!$C$5,"0.0%")&", absorbe "&Resumen!$C$6&")" -> Reducción de precio del Stage 1 (0.0%, absorbe IDOM) | K13: =-Resumen!$C$5*IF(Resumen!$C$6="IDOM",O12,K12) -> 0 | L13: =-Resumen!$C$5*IF(Resumen!$C$6="IDOM",0,L12) -> 0 | M13: =-Resumen!$C$5*IF(Resumen!$C$6="IDOM",0,M12) -> 0 | N13: =-Resumen!$C$5*IF(Resumen!$C$6="IDOM",0,N12) -> 0 | O13: =SUM(K13:N13) -> 0 | Q13: =-Resumen!$C$5*IF(Resumen!$C$6="IDOM",U12,Q12) -> 0 | R13: =-Resumen!$C$5*IF(Resumen!$C$6="IDOM",0,R12) -> 0 | S13: =-Resumen!$C$5*IF(Resumen!$C$6="IDOM",0,S12) -> 0 | T13: =-Resumen!$C$5*IF(Resumen!$C$6="IDOM",0,T12) -> 0 | U13: =SUM(Q13:T13) -> 0 | W13: =-Resumen!$C$5*IF(Resumen!$C$6="IDOM",AA12,W12) -> 0 | X13: =-Resumen!$C$5*IF(Resumen!$C$6="IDOM",0,X12) -> 0 | Y13: =-Resumen!$C$5*IF(Resumen!$C$6="IDOM",0,Y12) -> 0 | Z13: =-Resumen!$C$5*IF(Resumen!$C$6="IDOM",0,Z12) -> 0 | AA13: =SUM(W13:Z13) -> 0 | AC13: =-Resumen!$C$5*IF(Resumen!$C$6="IDOM",AG12,AC12) -> 0 | AD13: =-Resumen!$C$5*IF(Resumen!$C$6="IDOM",0,AD12) -> 0 | AE13: =-Resumen!$C$5*IF(Resumen!$C$6="IDOM",0,AE12) -> 0 | AF13: =-Resumen!$C$5*IF(Resumen!$C$6="IDOM",0,AF12) -> 0 | AG13: =SUM(AC13:AF13) -> 0
B14: TOTAL STAGE 1 | D14: =D12 -> 1435 | E14: =E12 -> 335082.83 | J14: =J12 -> 1435 | K14: =K12+K13 -> 133361.71 | L14: =L12+L13 -> 122885.02 | M14: =M12+M13 -> 0 | N14: =N12+N13 -> 78836.1 | O14: =O12+O13 -> 335082.83 | P14: =P12 -> 970 | Q14: =Q12+Q13 -> 133361.71 | R14: =R12+R13 -> 14817.968 | S14: =S12+S13 -> 0 | T14: =T12+T13 -> 78836.1 | U14: =U12+U13 -> 227015.77 | V14: =V12 -> 970 | W14: =W12+W13 -> 133361.71 | X14: =X12+X13 -> 14817.968 | Y14: =Y12+Y13 -> 0 | Z14: =Z12+Z13 -> 78836.1 | AA14: =AA12+AA13 -> 227015.77 | AB14: =AB12 -> 1435 | AC14: =AC12+AC13 -> 133361.71 | AD14: =AD12+AD13 -> 68851.492 | AE14: =AE12+AE13 -> 0 | AF14: =AF12+AF13 -> 78836.1 | AG14: =AG12+AG13 -> 281049.3
B16: Referencia: oferta original por empresa (sin escenarios ni ajustes) | E16: =SUM(F16:I16) -> 335082.83 | F16: =SUMPRODUCT($E$8:$E$11,F$8:F$11) -> 133361.71 | G16: =SUMPRODUCT($E$8:$E$11,G$8:G$11) -> 122885.02 | H16: =SUMPRODUCT($E$8:$E$11,H$8:H$11) -> 0 | I16: =SUMPRODUCT($E$8:$E$11,I$8:I$11) -> 78836.1

Sheet Stage 2
A1: Stage 2 · Concept Design — desglose por entregable y empresa (AUD)
A2: Importe = horas × tarifa de venta (pestaña Datos). Reparto por empresa según el tipo de cada entregable (pestaña Escenarios).
B4: Descontar el retrabajo | C4: No | D4: =Escenarios!$B$8 -> 0.35 | E4: Sí = se quita la reserva de retrabajo del precio de IDOM en el Stage 2 (recargo de D4 sobre sus tareas, editable en Escenarios).
A6: Oferta original | F6: Reparto | J6: =Escenarios!I$10&" · "&Escenarios!I$11 -> Escenario 1 · Original | P6: =Escenarios!J$10&" · "&Escenarios!J$11 -> Escenario 2 · Sin las 4 tareas de Plan Safe | V6: =Escenarios!K$10&" · "&Escenarios!K$11 -> Escenario 3 · Sin tareas Plan Safe ni SSC | AB6: =Escenarios!L$10&" · "&Escenarios!L$11 -> Escenario 4 · Sin SSC, tareas Plan Safe al 50 %
A7: Código | B7: Entregable | C7: Tipo | D7: Horas base | E7: Importe base | F7: % IDOM | G7: % Plan Safe | H7: % Synertec | I7: % INVAP | J7: Horas | K7: IDOM | L7: Plan Safe | M7: Synertec | N7: INVAP | O7: Total | P7: Horas | Q7: IDOM | R7: Plan Safe | S7: Synertec | T7: INVAP | U7: Total | V7: Horas | W7: IDOM | X7: Plan Safe | Y7: Synertec | Z7: INVAP | AA7: Total | AB7: Horas | AC7: IDOM | AD7: Plan Safe | AE7: Synertec | AF7: INVAP | AG7: Total
A8: E94 | B8: Radiological Zoning Layout drawing(s) | C8: =INDEX(Escenarios!$D$12:$D$36,MATCH($A8,Escenarios!$A$12:$A$36,0)) -> IDOM | D8: =SUMIFS(Datos!$H$5:$H$291,Datos!$E$5:$E$291,$A8,Datos!$F$5:$F$291,"S2") -> 185 | E8: =SUMIFS(Datos!$J$5:$J$291,Datos!$E$5:$E$291,$A8,Datos!$F$5:$F$291,"S2") -> 35206.5 | F8: =INDEX(Escenarios!$E$12:$E$36,MATCH($A8,Escenarios!$A$12:$A$36,0)) -> 1 | G8: =INDEX(Escenarios!$F$12:$F$36,MATCH($A8,Escenarios!$A$12:$A$36,0)) -> 0 | H8: =INDEX(Escenarios!$G$12:$G$36,MATCH($A8,Escenarios!$A$12:$A$36,0)) -> 0 | I8: =INDEX(Escenarios!$H$12:$H$36,MATCH($A8,Escenarios!$A$12:$A$36,0)) -> 0 | J8: =IF(INDEX(Escenarios!$I$12:$I$36,MATCH($A8,Escenarios!$A$12:$A$36,0))>0,$D8,0) -> 185 | K8: =$E8*INDEX(Escenarios!$I$12:$I$36,MATCH($A8,Escenarios!$A$12:$A$36,0))*F8 -> 35206.5 | L8: =$E8*INDEX(Escenarios!$I$12:$I$36,MATCH($A8,Escenarios!$A$12:$A$36,0))*G8 -> 0 | M8: =$E8*INDEX(Escenarios!$I$12:$I$36,MATCH($A8,Escenarios!$A$12:$A$36,0))*H8 -> 0 | N8: =$E8*INDEX(Escenarios!$I$12:$I$36,MATCH($A8,Escenarios!$A$12:$A$36,0))*I8 -> 0 | O8: =SUM(K8:N8) -> 35206.5 | P8: =IF(INDEX(Escenarios!$J$12:$J$36,MATCH($A8,Escenarios!$A$12:$A$36,0))>0,$D8,0) -> 185 | Q8: =$E8*INDEX(Escenarios!$J$12:$J$36,MATCH($A8,Escenarios!$A$12:$A$36,0))*F8 -> 35206.5 | R8: =$E8*INDEX(Escenarios!$J$12:$J$36,MATCH($A8,Escenarios!$A$12:$A$36,0))*G8 -> 0 | S8: =$E8*INDEX(Escenarios!$J$12:$J$36,MATCH($A8,Escenarios!$A$12:$A$36,0))*H8 -> 0 | T8: =$E8*INDEX(Escenarios!$J$12:$J$36,MATCH($A8,Escenarios!$A$12:$A$36,0))*I8 -> 0 | U8: =SUM(Q8:T8) -> 35206.5 | V8: =IF(INDEX(Escenarios!$K$12:$K$36,MATCH($A8,Escenarios!$A$12:$A$36,0))>0,$D8,0) -> 185 | W8: =$E8*INDEX(Escenarios!$K$12:$K$36,MATCH($A8,Escenarios!$A$12:$A$36,0))*F8 -> 35206.5 | X8: =$E8*INDEX(Escenarios!$K$12:$K$36,MATCH($A8,Escenarios!$A$12:$A$36,0))*G8 -> 0 | Y8: =$E8*INDEX(Escenarios!$K$12:$K$36,MATCH($A8,Escenarios!$A$12:$A$36,0))*H8 -> 0 | Z8: =$E8*INDEX(Escenarios!$K$12:$K$36,MATCH($A8,Escenarios!$A$12:$A$36,0))*I8 -> 0 | AA8: =SUM(W8:Z8) -> 35206.5 | AB8: =IF(INDEX(Escenarios!$L$12:$L$36,MATCH($A8,Escenarios!$A$12:$A$36,0))>0,$D8,0) -> 185 | AC8: =$E8*INDEX(Escenarios!$L$12:$L$36,MATCH($A8,Escenarios!$A$12:$A$36,0))*F8 -> 35206.5 | AD8: =$E8*INDEX(Escenarios!$L$12:$L$36,MATCH($A8,Escenarios!$A$12:$A$36,0))*G8 -> 0 | AE8: =$E8*INDEX(Escenarios!$L$12:$L$36,MATCH($A8,Escenarios!$A$12:$A$36,0))*H8 -> 0 | AF8: =$E8*INDEX(Escenarios!$L$12:$L$36,MATCH($A8,Escenarios!$A$12:$A$36,0))*I8 -> 0 | AG8: =SUM(AC8:AF8) -> 35206.5
A9: S1 | B9: Safety Assurance Plan / Safety Integration Plan | C9: =INDEX(Escenarios!$D$12:$D$36,MATCH($A9,Escenarios!$A$12:$A$36,0)) -> Compartido | D9: =SUMIFS(Datos!$H$5:$H$291,Datos!$E$5:$E$291,$A9,Datos!$F$5:$F$291,"S2") -> 1200 | E9: =SUMIFS(Datos!$J$5:$J$291,Datos!$E$5:$E$291,$A9,Datos!$F$5:$F$291,"S2") -> 284239.2 | F9: =INDEX(Escenarios!$E$12:$E$36,MATCH($A9,Escenarios!$A$12:$A$36,0)) -> 0.9 | G9: =INDEX(Escenarios!$F$12:$F$36,MATCH($A9,Escenarios!$A$12:$A$36,0)) -> 0.1 | H9: =INDEX(Escenarios!$G$12:$G$36,MATCH($A9,Escenarios!$A$12:$A$36,0)) -> 0 | I9: =INDEX(Escenarios!$H$12:$H$36,MATCH($A9,Escenarios!$A$12:$A$36,0)) -> 0 | J9: =IF(INDEX(Escenarios!$I$12:$I$36,MATCH($A9,Escenarios!$A$12:$A$36,0))>0,$D9,0) -> 1200 | K9: =$E9*INDEX(Escenarios!$I$12:$I$36,MATCH($A9,Escenarios!$A$12:$A$36,0))*F9 -> 255815.28 | L9: =$E9*INDEX(Escenarios!$I$12:$I$36,MATCH($A9,Escenarios!$A$12:$A$36,0))*G9 -> 28423.92 | M9: =$E9*INDEX(Escenarios!$I$12:$I$36,MATCH($A9,Escenarios!$A$12:$A$36,0))*H9 -> 0 | N9: =$E9*INDEX(Escenarios!$I$12:$I$36,MATCH($A9,Escenarios!$A$12:$A$36,0))*I9 -> 0 | O9: =SUM(K9:N9) -> 284239.2 | P9: =IF(INDEX(Escenarios!$J$12:$J$36,MATCH($A9,Escenarios!$A$12:$A$36,0))>0,$D9,0) -> 1200 | Q9: =$E9*INDEX(Escenarios!$J$12:$J$36,MATCH($A9,Escenarios!$A$12:$A$36,0))*F9 -> 255815.28 | R9: =$E9*INDEX(Escenarios!$J$12:$J$36,MATCH($A9,Escenarios!$A$12:$A$36,0))*G9 -> 28423.92 | S9: =$E9*INDEX(Escenarios!$J$12:$J$36,MATCH($A9,Escenarios!$A$12:$A$36,0))*H9 -> 0 | T9: =$E9*INDEX(Escenarios!$J$12:$J$36,MATCH($A9,Escenarios!$A$12:$A$36,0))*I9 -> 0 | U9: =SUM(Q9:T9) -> 284239.2 | V9: =IF(INDEX(Escenarios!$K$12:$K$36,MATCH($A9,Escenarios!$A$12:$A$36,0))>0,$D9,0) -> 1200 | W9: =$E9*INDEX(Escenarios!$K$12:$K$36,MATCH($A9,Escenarios!$A$12:$A$36,0))*F9 -> 255815.28 | X9: =$E9*INDEX(Escenarios!$K$12:$K$36,MATCH($A9,Escenarios!$A$12:$A$36,0))*G9 -> 28423.92 | Y9: =$E9*INDEX(Escenarios!$K$12:$K$36,MATCH($A9,Escenarios!$A$12:$A$36,0))*H9 -> 0 | Z9: =$E9*INDEX(Escenarios!$K$12:$K$36,MATCH($A9,Escenarios!$A$12:$A$36,0))*I9 -> 0 | AA9: =SUM(W9:Z9) -> 284239.2 | AB9: =IF(INDEX(Escenarios!$L$12:$L$36,MATCH($A9,Escenarios!$A$12:$A$36,0))>0,$D9,0) -> 1200 | AC9: =$E9*INDEX(Escenarios!$L$12:$L$36,MATCH($A9,Escenarios!$A$12:$A$36,0))*F9 -> 255815.28 | AD9: =$E9*INDEX(Escenarios!$L$12:$L$36,MATCH($A9,Escenarios!$A$12:$A$36,0))*G9 -> 28423.92 | AE9: =$E9*INDEX(Escenarios!$L$12:$L$36,MATCH($A9,Escenarios!$A$12:$A$36,0))*H9 -> 0 | AF9: =$E9*INDEX(Escenarios!$L$12:$L$36,MATCH($A9,Escenarios!$A$12:$A$36,0))*I9 -> 0 | AG9: =SUM(AC9:AF9) -> 284239.2
A10: S17 | B10: ALARP (Optioneering) Study | C10: =INDEX(Escenarios!$D$12:$D$36,MATCH($A10,Escenarios!$A$12:$A$36,0)) -> Compartido | D10: =SUMIFS(Datos!$H$5:$H$291,Datos!$E$5:$E$291,$A10,Datos!$F$5:$F$291,"S2") -> 385 | E10: =SUMIFS(Datos!$J$5:$J$291,Datos!$E$5:$E$291,$A10,Datos!$F$5:$F$291,"S2") -> 90335.175 | F10: =INDEX(Escenarios!$E$12:$E$36,MATCH($A10,Escenarios!$A$12:$A$36,0)) -> 0.9 | G10: =INDEX(Escenarios!$F$12:$F$36,MATCH($A10,Escenarios!$A$12:$A$36,0)) -> 0.1 | H10: =INDEX(Escenarios!$G$12:$G$36,MATCH($A10,Escenarios!$A$12:$A$36,0)) -> 0 | I10: =INDEX(Escenarios!$H$12:$H$36,MATCH($A10,Escenarios!$A$12:$A$36,0)) -> 0 | J10: =IF(INDEX(Escenarios!$I$12:$I$36,MATCH($A10,Escenarios!$A$12:$A$36,0))>0,$D10,0) -> 385 | K10: =$E10*INDEX(Escenarios!$I$12:$I$36,MATCH($A10,Escenarios!$A$12:$A$36,0))*F10 -> 81301.658 | L10: =$E10*INDEX(Escenarios!$I$12:$I$36,MATCH($A10,Escenarios!$A$12:$A$36,0))*G10 -> 9033.5175 | M10: =$E10*INDEX(Escenarios!$I$12:$I$36,MATCH($A10,Escenarios!$A$12:$A$36,0))*H10 -> 0 | N10: =$E10*INDEX(Escenarios!$I$12:$I$36,MATCH($A10,Escenarios!$A$12:$A$36,0))*I10 -> 0 | O10: =SUM(K10:N10) -> 90335.175 | P10: =IF(INDEX(Escenarios!$J$12:$J$36,MATCH($A10,Escenarios!$A$12:$A$36,0))>0,$D10,0) -> 385 | Q10: =$E10*INDEX(Escenarios!$J$12:$J$36,MATCH($A10,Escenarios!$A$12:$A$36,0))*F10 -> 81301.658 | R10: =$E10*INDEX(Escenarios!$J$12:$J$36,MATCH($A10,Escenarios!$A$12:$A$36,0))*G10 -> 9033.5175 | S10: =$E10*INDEX(Escenarios!$J$12:$J$36,MATCH($A10,Escenarios!$A$12:$A$36,0))*H10 -> 0 | T10: =$E10*INDEX(Escenarios!$J$12:$J$36,MATCH($A10,Escenarios!$A$12:$A$36,0))*I10 -> 0 | U10: =SUM(Q10:T10) -> 90335.175 | V10: =IF(INDEX(Escenarios!$K$12:$K$36,MATCH($A10,Escenarios!$A$12:$A$36,0))>0,$D10,0) -> 385 | W10: =$E10*INDEX(Escenarios!$K$12:$K$36,MATCH($A10,Escenarios!$A$12:$A$36,0))*F10 -> 81301.658 | X10: =$E10*INDEX(Escenarios!$K$12:$K$36,MATCH($A10,Escenarios!$A$12:$A$36,0))*G10 -> 9033.5175 | Y10: =$E10*INDEX(Escenarios!$K$12:$K$36,MATCH($A10,Escenarios!$A$12:$A$36,0))*H10 -> 0 | Z10: =$E10*INDEX(Escenarios!$K$12:$K$36,MATCH($A10,Escenarios!$A$12:$A$36,0))*I10 -> 0 | AA10: =SUM(W10:Z10) -> 90335.175 | AB10: =IF(INDEX(Escenarios!$L$12:$L$36,MATCH($A10,Escenarios!$A$12:$A$36,0))>0,$D10,0) -> 385 | AC10: =$E10*INDEX(Escenarios!$L$12:$L$36,MATCH($A10,Escenarios!$A$12:$A$36,0))*F10 -> 81301.658 | AD10: =$E10*INDEX(Escenarios!$L$12:$L$36,MATCH($A10,Escenarios!$A$12:$A$36,0))*G10 -> 9033.5175 | AE10: =$E10*INDEX(Escenarios!$L$12:$L$36,MATCH($A10,Escenarios!$A$12:$A$36,0))*H10 -> 0 | AF10: =$E10*INDEX(Escenarios!$L$12:$L$36,MATCH($A10,Escenarios!$A$12:$A$36,0))*I10 -> 0 | AG10: =SUM(AC10:AF10) -> 90335.175
A11: S24 | B11: Radiological Classification of Areas (RCA) | C11: =INDEX(Escenarios!$D$12:$D$36,MATCH($A11,Escenarios!$A$12:$A$36,0)) -> IDOM | D11: =SUMIFS(Datos!$H$5:$H$291,Datos!$E$5:$E$291,$A11,Datos!$F$5:$F$291,"S2") -> 280 | E11: =SUMIFS(Datos!$J$5:$J$291,Datos!$E$5:$E$291,$A11,Datos!$F$5:$F$291,"S2") -> 64455.825 | F11: =INDEX(Escenarios!$E$12:$E$36,MATCH($A11,Escenarios!$A$12:$A$36,0)) -> 1 | G11: =INDEX(Escenarios!$F$12:$F$36,MATCH($A11,Escenarios!$A$12:$A$36,0)) -> 0 | H11: =INDEX(Escenarios!$G$12:$G$36,MATCH($A11,Escenarios!$A$12:$A$36,0)) -> 0 | I11: =INDEX(Escenarios!$H$12:$H$36,MATCH($A11,Escenarios!$A$12:$A$36,0)) -> 0 | J11: =IF(INDEX(Escenarios!$I$12:$I$36,MATCH($A11,Escenarios!$A$12:$A$36,0))>0,$D11,0) -> 280 | K11: =$E11*INDEX(Escenarios!$I$12:$I$36,MATCH($A11,Escenarios!$A$12:$A$36,0))*F11 -> 64455.825 | L11: =$E11*INDEX(Escenarios!$I$12:$I$36,MATCH($A11,Escenarios!$A$12:$A$36,0))*G11 -> 0 | M11: =$E11*INDEX(Escenarios!$I$12:$I$36,MATCH($A11,Escenarios!$A$12:$A$36,0))*H11 -> 0 | N11: =$E11*INDEX(Escenarios!$I$12:$I$36,MATCH($A11,Escenarios!$A$12:$A$36,0))*I11 -> 0 | O11: =SUM(K11:N11) -> 64455.825 | P11: =IF(INDEX(Escenarios!$J$12:$J$36,MATCH($A11,Escenarios!$A$12:$A$36,0))>0,$D11,0) -> 280 | Q11: =$E11*INDEX(Escenarios!$J$12:$J$36,MATCH($A11,Escenarios!$A$12:$A$36,0))*F11 -> 64455.825 | R11: =$E11*INDEX(Escenarios!$J$12:$J$36,MATCH($A11,Escenarios!$A$12:$A$36,0))*G11 -> 0 | S11: =$E11*INDEX(Escenarios!$J$12:$J$36,MATCH($A11,Escenarios!$A$12:$A$36,0))*H11 -> 0 | T11: =$E11*INDEX(Escenarios!$J$12:$J$36,MATCH($A11,Escenarios!$A$12:$A$36,0))*I11 -> 0 | U11: =SUM(Q11:T11) -> 64455.825 | V11: =IF(INDEX(Escenarios!$K$12:$K$36,MATCH($A11,Escenarios!$A$12:$A$36,0))>0,$D11,0) -> 280 | W11: =$E11*INDEX(Escenarios!$K$12:$K$36,MATCH($A11,Escenarios!$A$12:$A$36,0))*F11 -> 64455.825 | X11: =$E11*INDEX(Escenarios!$K$12:$K$36,MATCH($A11,Escenarios!$A$12:$A$36,0))*G11 -> 0 | Y11: =$E11*INDEX(Escenarios!$K$12:$K$36,MATCH($A11,Escenarios!$A$12:$A$36,0))*H11 -> 0 | Z11: =$E11*INDEX(Escenarios!$K$12:$K$36,MATCH($A11,Escenarios!$A$12:$A$36,0))*I11 -> 0 | AA11: =SUM(W11:Z11) -> 64455.825 | AB11: =IF(INDEX(Escenarios!$L$12:$L$36,MATCH($A11,Escenarios!$A$12:$A$36,0))>0,$D11,0) -> 280 | AC11: =$E11*INDEX(Escenarios!$L$12:$L$36,MATCH($A11,Escenarios!$A$12:$A$36,0))*F11 -> 64455.825 | AD11: =$E11*INDEX(Escenarios!$L$12:$L$36,MATCH($A11,Escenarios!$A$12:$A$36,0))*G11 -> 0 | AE11: =$E11*INDEX(Escenarios!$L$12:$L$36,MATCH($A11,Escenarios!$A$12:$A$36,0))*H11 -> 0 | AF11: =$E11*INDEX(Escenarios!$L$12:$L$36,MATCH($A11,Escenarios!$A$12:$A$36,0))*I11 -> 0 | AG11: =SUM(AC11:AF11) -> 64455.825
A12: S26 | B12: Structures Systems and Components (SSC) Categorisation Report | C12: =INDEX(Escenarios!$D$12:$D$36,MATCH($A12,Escenarios!$A$12:$A$36,0)) -> IDOM | D12: =SUMIFS(Datos!$H$5:$H$291,Datos!$E$5:$E$291,$A12,Datos!$F$5:$F$291,"S2") -> 270 | E12: =SUMIFS(Datos!$J$5:$J$291,Datos!$E$5:$E$291,$A12,Datos!$F$5:$F$291,"S2") -> 62552.175 | F12: =INDEX(Escenarios!$E$12:$E$36,MATCH($A12,Escenarios!$A$12:$A$36,0)) -> 1 | G12: =INDEX(Escenarios!$F$12:$F$36,MATCH($A12,Escenarios!$A$12:$A$36,0)) -> 0 | H12: =INDEX(Escenarios!$G$12:$G$36,MATCH($A12,Escenarios!$A$12:$A$36,0)) -> 0 | I12: =INDEX(Escenarios!$H$12:$H$36,MATCH($A12,Escenarios!$A$12:$A$36,0)) -> 0 | J12: =IF(INDEX(Escenarios!$I$12:$I$36,MATCH($A12,Escenarios!$A$12:$A$36,0))>0,$D12,0) -> 270 | K12: =$E12*INDEX(Escenarios!$I$12:$I$36,MATCH($A12,Escenarios!$A$12:$A$36,0))*F12 -> 62552.175 | L12: =$E12*INDEX(Escenarios!$I$12:$I$36,MATCH($A12,Escenarios!$A$12:$A$36,0))*G12 -> 0 | M12: =$E12*INDEX(Escenarios!$I$12:$I$36,MATCH($A12,Escenarios!$A$12:$A$36,0))*H12 -> 0 | N12: =$E12*INDEX(Escenarios!$I$12:$I$36,MATCH($A12,Escenarios!$A$12:$A$36,0))*I12 -> 0 | O12: =SUM(K12:N12) -> 62552.175 | P12: =IF(INDEX(Escenarios!$J$12:$J$36,MATCH($A12,Escenarios!$A$12:$A$36,0))>0,$D12,0) -> 270 | Q12: =$E12*INDEX(Escenarios!$J$12:$J$36,MATCH($A12,Escenarios!$A$12:$A$36,0))*F12 -> 62552.175 | R12: =$E12*INDEX(Escenarios!$J$12:$J$36,MATCH($A12,Escenarios!$A$12:$A$36,0))*G12 -> 0 | S12: =$E12*INDEX(Escenarios!$J$12:$J$36,MATCH($A12,Escenarios!$A$12:$A$36,0))*H12 -> 0 | T12: =$E12*INDEX(Escenarios!$J$12:$J$36,MATCH($A12,Escenarios!$A$12:$A$36,0))*I12 -> 0 | U12: =SUM(Q12:T12) -> 62552.175 | V12: =IF(INDEX(Escenarios!$K$12:$K$36,MATCH($A12,Escenarios!$A$12:$A$36,0))>0,$D12,0) -> 0 | W12: =$E12*INDEX(Escenarios!$K$12:$K$36,MATCH($A12,Escenarios!$A$12:$A$36,0))*F12 -> 0 | X12: =$E12*INDEX(Escenarios!$K$12:$K$36,MATCH($A12,Escenarios!$A$12:$A$36,0))*G12 -> 0 | Y12: =$E12*INDEX(Escenarios!$K$12:$K$36,MATCH($A12,Escenarios!$A$12:$A$36,0))*H12 -> 0 | Z12: =$E12*INDEX(Escenarios!$K$12:$K$36,MATCH($A12,Escenarios!$A$12:$A$36,0))*I12 -> 0 | AA12: =SUM(W12:Z12) -> 0 | AB12: =IF(INDEX(Escenarios!$L$12:$L$36,MATCH($A12,Escenarios!$A$12:$A$36,0))>0,$D12,0) -> 0 | AC12: =$E12*INDEX(Escenarios!$L$12:$L$36,MATCH($A12,Escenarios!$A$12:$A$36,0))*F12 -> 0 | AD12: =$E12*INDEX(Escenarios!$L$12:$L$36,MATCH($A12,Escenarios!$A$12:$A$36,0))*G12 -> 0 | AE12: =$E12*INDEX(Escenarios!$L$12:$L$36,MATCH($A12,Escenarios!$A$12:$A$36,0))*H12 -> 0 | AF12: =$E12*INDEX(Escenarios!$L$12:$L$36,MATCH($A12,Escenarios!$A$12:$A$36,0))*I12 -> 0 | AG12: =SUM(AC12:AF12) -> 0
A13: S27 | B13: Structures Systems and Components (SSC) Register | C13: =INDEX(Escenarios!$D$12:$D$36,MATCH($A13,Escenarios!$A$12:$A$36,0)) -> IDOM | D13: =SUMIFS(Datos!$H$5:$H$291,Datos!$E$5:$E$291,$A13,Datos!$F$5:$F$291,"S2") -> 165 | E13: =SUMIFS(Datos!$J$5:$J$291,Datos!$E$5:$E$291,$A13,Datos!$F$5:$F$291,"S2") -> 37183.65 | F13: =INDEX(Escenarios!$E$12:$E$36,MATCH($A13,Escenarios!$A$12:$A$36,0)) -> 1 | G13: =INDEX(Escenarios!$F$12:$F$36,MATCH($A13,Escenarios!$A$12:$A$36,0)) -> 0 | H13: =INDEX(Escenarios!$G$12:$G$36,MATCH($A13,Escenarios!$A$12:$A$36,0)) -> 0 | I13: =INDEX(Escenarios!$H$12:$H$36,MATCH($A13,Escenarios!$A$12:$A$36,0)) -> 0 | J13: =IF(INDEX(Escenarios!$I$12:$I$36,MATCH($A13,Escenarios!$A$12:$A$36,0))>0,$D13,0) -> 165 | K13: =$E13*INDEX(Escenarios!$I$12:$I$36,MATCH($A13,Escenarios!$A$12:$A$36,0))*F13 -> 37183.65 | L13: =$E13*INDEX(Escenarios!$I$12:$I$36,MATCH($A13,Escenarios!$A$12:$A$36,0))*G13 -> 0 | M13: =$E13*INDEX(Escenarios!$I$12:$I$36,MATCH($A13,Escenarios!$A$12:$A$36,0))*H13 -> 0 | N13: =$E13*INDEX(Escenarios!$I$12:$I$36,MATCH($A13,Escenarios!$A$12:$A$36,0))*I13 -> 0 | O13: =SUM(K13:N13) -> 37183.65 | P13: =IF(INDEX(Escenarios!$J$12:$J$36,MATCH($A13,Escenarios!$A$12:$A$36,0))>0,$D13,0) -> 165 | Q13: =$E13*INDEX(Escenarios!$J$12:$J$36,MATCH($A13,Escenarios!$A$12:$A$36,0))*F13 -> 37183.65 | R13: =$E13*INDEX(Escenarios!$J$12:$J$36,MATCH($A13,Escenarios!$A$12:$A$36,0))*G13 -> 0 | S13: =$E13*INDEX(Escenarios!$J$12:$J$36,MATCH($A13,Escenarios!$A$12:$A$36,0))*H13 -> 0 | T13: =$E13*INDEX(Escenarios!$J$12:$J$36,MATCH($A13,Escenarios!$A$12:$A$36,0))*I13 -> 0 | U13: =SUM(Q13:T13) -> 37183.65 | V13: =IF(INDEX(Escenarios!$K$12:$K$36,MATCH($A13,Escenarios!$A$12:$A$36,0))>0,$D13,0) -> 0 | W13: =$E13*INDEX(Escenarios!$K$12:$K$36,MATCH($A13,Escenarios!$A$12:$A$36,0))*F13 -> 0 | X13: =$E13*INDEX(Escenarios!$K$12:$K$36,MATCH($A13,Escenarios!$A$12:$A$36,0))*G13 -> 0 | Y13: =$E13*INDEX(Escenarios!$K$12:$K$36,MATCH($A13,Escenarios!$A$12:$A$36,0))*H13 -> 0 | Z13: =$E13*INDEX(Escenarios!$K$12:$K$36,MATCH($A13,Escenarios!$A$12:$A$36,0))*I13 -> 0 | AA13: =SUM(W13:Z13) -> 0 | AB13: =IF(INDEX(Escenarios!$L$12:$L$36,MATCH($A13,Escenarios!$A$12:$A$36,0))>0,$D13,0) -> 0 | AC13: =$E13*INDEX(Escenarios!$L$12:$L$36,MATCH($A13,Escenarios!$A$12:$A$36,0))*F13 -> 0 | AD13: =$E13*INDEX(Escenarios!$L$12:$L$36,MATCH($A13,Escenarios!$A$12:$A$36,0))*G13 -> 0 | AE13: =$E13*INDEX(Escenarios!$L$12:$L$36,MATCH($A13,Escenarios!$A$12:$A$36,0))*H13 -> 0 | AF13: =$E13*INDEX(Escenarios!$L$12:$L$36,MATCH($A13,Escenarios!$A$12:$A$36,0))*I13 -> 0 | AG13: =SUM(AC13:AF13) -> 0
A14: S2 | B14: Human Factors Assurance Plan / Human Factors Integration Plan (HFIP) | C14: =INDEX(Escenarios!$D$12:$D$36,MATCH($A14,Escenarios!$A$12:$A$36,0)) -> Plan Safe | D14: =SUMIFS(Datos!$H$5:$H$291,Datos!$E$5:$E$291,$A14,Datos!$F$5:$F$291,"S2") -> 380 | E14: =SUMIFS(Datos!$J$5:$J$291,Datos!$E$5:$E$291,$A14,Datos!$F$5:$F$291,"S2") -> 88244.1 | F14: =INDEX(Escenarios!$E$12:$E$36,MATCH($A14,Escenarios!$A$12:$A$36,0)) -> 0 | G14: =INDEX(Escenarios!$F$12:$F$36,MATCH($A14,Escenarios!$A$12:$A$36,0)) -> 1 | H14: =INDEX(Escenarios!$G$12:$G$36,MATCH($A14,Escenarios!$A$12:$A$36,0)) -> 0 | I14: =INDEX(Escenarios!$H$12:$H$36,MATCH($A14,Escenarios!$A$12:$A$36,0)) -> 0 | J14: =IF(INDEX(Escenarios!$I$12:$I$36,MATCH($A14,Escenarios!$A$12:$A$36,0))>0,$D14,0) -> 380 | K14: =$E14*INDEX(Escenarios!$I$12:$I$36,MATCH($A14,Escenarios!$A$12:$A$36,0))*F14 -> 0 | L14: =$E14*INDEX(Escenarios!$I$12:$I$36,MATCH($A14,Escenarios!$A$12:$A$36,0))*G14 -> 88244.1 | M14: =$E14*INDEX(Escenarios!$I$12:$I$36,MATCH($A14,Escenarios!$A$12:$A$36,0))*H14 -> 0 | N14: =$E14*INDEX(Escenarios!$I$12:$I$36,MATCH($A14,Escenarios!$A$12:$A$36,0))*I14 -> 0 | O14: =SUM(K14:N14) -> 88244.1 | P14: =IF(INDEX(Escenarios!$J$12:$J$36,MATCH($A14,Escenarios!$A$12:$A$36,0))>0,$D14,0) -> 0 | Q14: =$E14*INDEX(Escenarios!$J$12:$J$36,MATCH($A14,Escenarios!$A$12:$A$36,0))*F14 -> 0 | R14: =$E14*INDEX(Escenarios!$J$12:$J$36,MATCH($A14,Escenarios!$A$12:$A$36,0))*G14 -> 0 | S14: =$E14*INDEX(Escenarios!$J$12:$J$36,MATCH($A14,Escenarios!$A$12:$A$36,0))*H14 -> 0 | T14: =$E14*INDEX(Escenarios!$J$12:$J$36,MATCH($A14,Escenarios!$A$12:$A$36,0))*I14 -> 0 | U14: =SUM(Q14:T14) -> 0 | V14: =IF(INDEX(Escenarios!$K$12:$K$36,MATCH($A14,Escenarios!$A$12:$A$36,0))>0,$D14,0) -> 0 | W14: =$E14*INDEX(Escenarios!$K$12:$K$36,MATCH($A14,Escenarios!$A$12:$A$36,0))*F14 -> 0 | X14: =$E14*INDEX(Escenarios!$K$12:$K$36,MATCH($A14,Escenarios!$A$12:$A$36,0))*G14 -> 0 | Y14: =$E14*INDEX(Escenarios!$K$12:$K$36,MATCH($A14,Escenarios!$A$12:$A$36,0))*H14 -> 0 | Z14: =$E14*INDEX(Escenarios!$K$12:$K$36,MATCH($A14,Escenarios!$A$12:$A$36,0))*I14 -> 0 | AA14: =SUM(W14:Z14) -> 0 | AB14: =IF(INDEX(Escenarios!$L$12:$L$36,MATCH($A14,Escenarios!$A$12:$A$36,0))>0,$D14,0) -> 380 | AC14: =$E14*INDEX(Escenarios!$L$12:$L$36,MATCH($A14,Escenarios!$A$12:$A$36,0))*F14 -> 0 | AD14: =$E14*INDEX(Escenarios!$L$12:$L$36,MATCH($A14,Escenarios!$A$12:$A$36,0))*G14 -> 44122.05 | AE14: =$E14*INDEX(Escenarios!$L$12:$L$36,MATCH($A14,Escenarios!$A$12:$A$36,0))*H14 -> 0 | AF14: =$E14*INDEX(Escenarios!$L$12:$L$36,MATCH($A14,Escenarios!$A$12:$A$36,0))*I14 -> 0 | AG14: =SUM(AC14:AF14) -> 44122.05
A15: S3 | B15: Human Factors Hazards Identification and Control Plan (HFHICP) | C15: =INDEX(Escenarios!$D$12:$D$36,MATCH($A15,Escenarios!$A$12:$A$36,0)) -> Plan Safe | D15: =SUMIFS(Datos!$H$5:$H$291,Datos!$E$5:$E$291,$A15,Datos!$F$5:$F$291,"S2") -> 305 | E15: =SUMIFS(Datos!$J$5:$J$291,Datos!$E$5:$E$291,$A15,Datos!$F$5:$F$291,"S2") -> 70622.475 | F15: =INDEX(Escenarios!$E$12:$E$36,MATCH($A15,Escenarios!$A$12:$A$36,0)) -> 0 | G15: =INDEX(Escenarios!$F$12:$F$36,MATCH($A15,Escenarios!$A$12:$A$36,0)) -> 1 | H15: =INDEX(Escenarios!$G$12:$G$36,MATCH($A15,Escenarios!$A$12:$A$36,0)) -> 0 | I15: =INDEX(Escenarios!$H$12:$H$36,MATCH($A15,Escenarios!$A$12:$A$36,0)) -> 0 | J15: =IF(INDEX(Escenarios!$I$12:$I$36,MATCH($A15,Escenarios!$A$12:$A$36,0))>0,$D15,0) -> 305 | K15: =$E15*INDEX(Escenarios!$I$12:$I$36,MATCH($A15,Escenarios!$A$12:$A$36,0))*F15 -> 0 | L15: =$E15*INDEX(Escenarios!$I$12:$I$36,MATCH($A15,Escenarios!$A$12:$A$36,0))*G15 -> 70622.475 | M15: =$E15*INDEX(Escenarios!$I$12:$I$36,MATCH($A15,Escenarios!$A$12:$A$36,0))*H15 -> 0 | N15: =$E15*INDEX(Escenarios!$I$12:$I$36,MATCH($A15,Escenarios!$A$12:$A$36,0))*I15 -> 0 | O15: =SUM(K15:N15) -> 70622.475 | P15: =IF(INDEX(Escenarios!$J$12:$J$36,MATCH($A15,Escenarios!$A$12:$A$36,0))>0,$D15,0) -> 0 | Q15: =$E15*INDEX(Escenarios!$J$12:$J$36,MATCH($A15,Escenarios!$A$12:$A$36,0))*F15 -> 0 | R15: =$E15*INDEX(Escenarios!$J$12:$J$36,MATCH($A15,Escenarios!$A$12:$A$36,0))*G15 -> 0 | S15: =$E15*INDEX(Escenarios!$J$12:$J$36,MATCH($A15,Escenarios!$A$12:$A$36,0))*H15 -> 0 | T15: =$E15*INDEX(Escenarios!$J$12:$J$36,MATCH($A15,Escenarios!$A$12:$A$36,0))*I15 -> 0 | U15: =SUM(Q15:T15) -> 0 | V15: =IF(INDEX(Escenarios!$K$12:$K$36,MATCH($A15,Escenarios!$A$12:$A$36,0))>0,$D15,0) -> 0 | W15: =$E15*INDEX(Escenarios!$K$12:$K$36,MATCH($A15,Escenarios!$A$12:$A$36,0))*F15 -> 0 | X15: =$E15*INDEX(Escenarios!$K$12:$K$36,MATCH($A15,Escenarios!$A$12:$A$36,0))*G15 -> 0 | Y15: =$E15*INDEX(Escenarios!$K$12:$K$36,MATCH($A15,Escenarios!$A$12:$A$36,0))*H15 -> 0 | Z15: =$E15*INDEX(Escenarios!$K$12:$K$36,MATCH($A15,Escenarios!$A$12:$A$36,0))*I15 -> 0 | AA15: =SUM(W15:Z15) -> 0 | AB15: =IF(INDEX(Escenarios!$L$12:$L$36,MATCH($A15,Escenarios!$A$12:$A$36,0))>0,$D15,0) -> 305 | AC15: =$E15*INDEX(Escenarios!$L$12:$L$36,MATCH($A15,Escenarios!$A$12:$A$36,0))*F15 -> 0 | AD15: =$E15*INDEX(Escenarios!$L$12:$L$36,MATCH($A15,Escenarios!$A$12:$A$36,0))*G15 -> 35311.238 | AE15: =$E15*INDEX(Escenarios!$L$12:$L$36,MATCH($A15,Escenarios!$A$12:$A$36,0))*H15 -> 0 | AF15: =$E15*INDEX(Escenarios!$L$12:$L$36,MATCH($A15,Escenarios!$A$12:$A$36,0))*I15 -> 0 | AG15: =SUM(AC15:AF15) -> 35311.238
B16: Subtotal Stage 2 (entregables) | D16: =SUM(D8:D15) -> 3170 | E16: =SUM(E8:E15) -> 732839.1 | J16: =SUM(J8:J15) -> 3170 | K16: =SUM(K8:K15) -> 536515.09 | L16: =SUM(L8:L15) -> 196324.01 | M16: =SUM(M8:M15) -> 0 | N16: =SUM(N8:N15) -> 0 | O16: =SUM(O8:O15) -> 732839.1 | P16: =SUM(P8:P15) -> 2485 | Q16: =SUM(Q8:Q15) -> 536515.09 | ... AG16: =SUM(AG8:AG15) -> 553669.99
B17: ="Retrabajo descontado (recargo "&TEXT(Escenarios!$B$8,"0%")&" sobre las tareas de IDOM): "&$C$4 -> Retrabajo descontado (recargo 35% sobre las tareas de IDOM): No | K17: =-IF($C$4="Sí",K16*Escenarios!$B$8/(1+Escenarios!$B$8),0) -> 0 | L17: 0 | M17: 0 | N17: 0 | O17: =SUM(K17:N17) -> 0 | Q17: =-IF($C$4="Sí",Q16*Escenarios!$B$8/(1+Escenarios!$B$8),0) -> 0 | R17: 0 | S17: 0 | T17: 0 | U17: =SUM(Q17:T17) -> 0 | W17: =-IF($C$4="Sí",W16*Escenarios!$B$8/(1+Escenarios!$B$8),0) -> 0 | X17: 0 | Y17: 0 | Z17: 0 | AA17: =SUM(W17:Z17) -> 0 | AC17: =-IF($C$4="Sí",AC16*Escenarios!$B$8/(1+Escenarios!$B$8),0) -> 0 | AD17: 0 | AE17: 0 | AF17: 0 | AG17: =SUM(AC17:AF17) -> 0
B18: TOTAL STAGE 2 | D18: =D16 -> 3170 | E18: =E16 -> 732839.1 | J18: =J16 -> 3170 | K18: =K16+K17 -> 536515.09 | L18: =L16+L17 -> 196324.01 | M18: =M16+M17 -> 0 | N18: =N16+N17 -> 0 | O18: =O16+O17 -> 732839.1 | P18: =P16 -> 2485 | Q18: =Q16+Q17 -> 536515.09 | R18: =R16+R17 -> 37457.438 | S18: =S16+S17 -> 0 | T18: =T16+T17 -> 0 | U18: =U16+U17 -> 573972.53 | V18: =V16 -> 2050 | W18: =W16+W17 -> 436779.26 | X18: =X16+X17 -> 37457.438 | Y18: =Y16+Y17 -> 0 | Z18: =Z16+Z17 -> 0 | AA18: =AA16+AA17 -> 474236.7 | AB18: =AB16 -> 2735 | AC18: =AC16+AC17 -> 436779.26 | AD18: =AD16+AD17 -> 116890.73 | AE18: =AE16+AE17 -> 0 | AF18: =AF16+AF17 -> 0 | AG18: =AG16+AG17 -> 553669.99
B20: Referencia: oferta original por empresa (sin escenarios ni ajustes) | E20: =SUM(F20:I20) -> 732839.1 | F20: =SUMPRODUCT($E$8:$E$15,F$8:F$15) -> 536515.09 | G20: =SUMPRODUCT($E$8:$E$15,G$8:G$15) -> 196324.01 | H20: =SUMPRODUCT($E$8:$E$15,H$8:H$15) -> 0 | I20: =SUMPRODUCT($E$8:$E$15,I$8:I$15) -> 0

Sheet Stage 3
A1: Stage 3 · Preliminary Design — desglose por entregable y empresa (AUD)
A2: Importe = horas × tarifa de venta (pestaña Datos). Reparto por empresa según el tipo de cada entregable (pestaña Escenarios).
A6: Oferta original | F6: Reparto | J6: =Escenarios!I$10&" · "&Escenarios!I$11 -> Escenario 1 · Original | P6: =Escenarios!J$10&" · "&Escenarios!J$11 -> Escenario 2 · Sin las 4 tareas de Plan Safe | V6: =Escenarios!K$10&" · "&Escenarios!K$11 -> Escenario 3 · Sin tareas Plan Safe ni SSC | AB6: =Escenarios!L$10&" · "&Escenarios!L$11 -> Escenario 4 · Sin SSC, tareas Plan Safe al 50 %
A7: Código | B7: Entregable | C7: Tipo | D7: Horas base | E7: Importe base | F7: % IDOM | G7: % Plan Safe | H7: % Synertec | I7: % INVAP | J7: Horas | K7: IDOM | L7: Plan Safe | M7: Synertec | N7: INVAP | O7: Total | P7: Horas | Q7: IDOM | R7: Plan Safe | S7: Synertec | T7: INVAP | U7: Total | V7: Horas | W7: IDOM | X7: Plan Safe | Y7: Synertec | Z7: INVAP | AA7: Total | AB7: Horas | AC7: IDOM | AD7: Plan Safe | AE7: Synertec | AF7: INVAP | AG7: Total
A8: E94 | B8: Radiological Zoning Layout drawing(s) | C8: =INDEX(Escenarios!$D$12:$D$36,MATCH($A8,Escenarios!$A$12:$A$36,0)) -> IDOM | D8: =SUMIFS(Datos!$H$5:$H$291,Datos!$E$5:$E$291,$A8,Datos!$F$5:$F$291,"S3") -> 315 | E8: =SUMIFS(Datos!$J$5:$J$291,Datos!$E$5:$E$291,$A8,Datos!$F$5:$F$291,"S3") -> 58869.825 | F8: =INDEX(Escenarios!$E$12:$E$36,MATCH($A8,Escenarios!$A$12:$A$36,0)) -> 1 | G8: =INDEX(Escenarios!$F$12:$F$36,MATCH($A8,Escenarios!$A$12:$A$36,0)) -> 0 | H8: =INDEX(Escenarios!$G$12:$G$36,MATCH($A8,Escenarios!$A$12:$A$36,0)) -> 0 | I8: =INDEX(Escenarios!$H$12:$H$36,MATCH($A8,Escenarios!$A$12:$A$36,0)) -> 0 | J8: =IF(INDEX(Escenarios!$I$12:$I$36,MATCH($A8,Escenarios!$A$12:$A$36,0))>0,$D8,0) -> 315 | K8: =$E8*INDEX(Escenarios!$I$12:$I$36,MATCH($A8,Escenarios!$A$12:$A$36,0))*F8 -> 58869.825 | L8: =$E8*INDEX(Escenarios!$I$12:$I$36,MATCH($A8,Escenarios!$A$12:$A$36,0))*G8 -> 0 | M8: =$E8*INDEX(Escenarios!$I$12:$I$36,MATCH($A8,Escenarios!$A$12:$A$36,0))*H8 -> 0 | N8: =$E8*INDEX(Escenarios!$I$12:$I$36,MATCH($A8,Escenarios!$A$12:$A$36,0))*I8 -> 0 | O8: =SUM(K8:N8) -> 58869.825 | P8: =IF(INDEX(Escenarios!$J$12:$J$36,MATCH($A8,Escenarios!$A$12:$A$36,0))>0,$D8,0) -> 315 | Q8: =$E8*INDEX(Escenarios!$J$12:$J$36,MATCH($A8,Escenarios!$A$12:$A$36,0))*F8 -> 58869.825 | R8: =$E8*INDEX(Escenarios!$J$12:$J$36,MATCH($A8,Escenarios!$A$12:$A$36,0))*G8 -> 0 | S8: =$E8*INDEX(Escenarios!$J$12:$J$36,MATCH($A8,Escenarios!$A$12:$A$36,0))*H8 -> 0 | T8: =$E8*INDEX(Escenarios!$J$12:$J$36,MATCH($A8,Escenarios!$A$12:$A$36,0))*I8 -> 0 | U8: =SUM(Q8:T8) -> 58869.825 | V8: =IF(INDEX(Escenarios!$K$12:$K$36,MATCH($A8,Escenarios!$A$12:$A$36,0))>0,$D8,0) -> 315 | W8: =$E8*INDEX(Escenarios!$K$12:$K$36,MATCH($A8,Escenarios!$A$12:$A$36,0))*F8 -> 58869.825 | X8: =$E8*INDEX(Escenarios!$K$12:$K$36,MATCH($A8,Escenarios!$A$12:$A$36,0))*G8 -> 0 | Y8: =$E8*INDEX(Escenarios!$K$12:$K$36,MATCH($A8,Escenarios!$A$12:$A$36,0))*H8 -> 0 | Z8: =$E8*INDEX(Escenarios!$K$12:$K$36,MATCH($A8,Escenarios!$A$12:$A$36,0))*I8 -> 0 | AA8: =SUM(W8:Z8) -> 58869.825 | AB8: =IF(INDEX(Escenarios!$L$12:$L$36,MATCH($A8,Escenarios!$A$12:$A$36,0))>0,$D8,0) -> 315 | AC8: =$E8*INDEX(Escenarios!$L$12:$L$36,MATCH($A8,Escenarios!$A$12:$A$36,0))*F8 -> 58869.825 | AD8: =$E8*INDEX(Escenarios!$L$12:$L$36,MATCH($A8,Escenarios!$A$12:$A$36,0))*G8 -> 0 | AE8: =$E8*INDEX(Escenarios!$L$12:$L$36,MATCH($A8,Escenarios!$A$12:$A$36,0))*H8 -> 0 | AF8: =$E8*INDEX(Escenarios!$L$12:$L$36,MATCH($A8,Escenarios!$A$12:$A$36,0))*I8 -> 0 | AG8: =SUM(AC8:AF8) -> 58869.825
A9: S9 | B9: Deterministic Safety Assessment(s) (DSA) / Inherent Risk Assessment(s) | C9: =INDEX(Escenarios!$D$12:$D$36,MATCH($A9,Escenarios!$A$12:$A$36,0)) -> Compartido | D9: =SUMIFS(Datos!$H$5:$H$291,Datos!$E$5:$E$291,$A9,Datos!$F$5:$F$291,"S3") -> 1385 | E9: =SUMIFS(Datos!$J$5:$J$291,Datos!$E$5:$E$291,$A9,Datos!$F$5:$F$291,"S3") -> 323392.65 | F9: =INDEX(Escenarios!$E$12:$E$36,MATCH($A9,Escenarios!$A$12:$A$36,0)) -> 0.9 | G9: =INDEX(Escenarios!$F$12:$F$36,MATCH($A9,Escenarios!$A$12:$A$36,0)) -> 0.1 | H9: =INDEX(Escenarios!$G$12:$G$36,MATCH($A9,Escenarios!$A$12:$A$36,0)) -> 0 | I9: =INDEX(Escenarios!$H$12:$H$36,MATCH($A9,Escenarios!$A$12:$A$36,0)) -> 0 | J9: =IF(INDEX(Escenarios!$I$12:$I$36,MATCH($A9,Escenarios!$A$12:$A$36,0))>0,$D9,0) -> 1385 | K9: =$E9*INDEX(Escenarios!$I$12:$I$36,MATCH($A9,Escenarios!$A$12:$A$36,0))*F9 -> 291053.39 | L9: =$E9*INDEX(Escenarios!$I$12:$I$36,MATCH($A9,Escenarios!$A$12:$A$36,0))*G9 -> 32339.265 | M9: =$E9*INDEX(Escenarios!$I$12:$I$36,MATCH($A9,Escenarios!$A$12:$A$36,0))*H9 -> 0 | N9: =$E9*INDEX(Escenarios!$I$12:$I$36,MATCH($A9,Escenarios!$A$12:$A$36,0))*I9 -> 0 | O9: =SUM(K9:N9) -> 323392.65 | P9: =IF(INDEX(Escenarios!$J$12:$J$36,MATCH($A9,Escenarios!$A$12:$A$36,0))>0,$D9,0) -> 1385 | Q9: =$E9*INDEX(Escenarios!$J$12:$J$36,MATCH($A9,Escenarios!$A$12:$A$36,0))*F9 -> 291053.39 | R9: =$E9*INDEX(Escenarios!$J$12:$J$36,MATCH($A9,Escenarios!$A$12:$A$36,0))*G9 -> 32339.265 | S9: =$E9*INDEX(Escenarios!$J$12:$J$36,MATCH($A9,Escenarios!$A$12:$A$36,0))*H9 -> 0 | T9: =$E9*INDEX(Escenarios!$J$12:$J$36,MATCH($A9,Escenarios!$A$12:$A$36,0))*I9 -> 0 | U9: =SUM(Q9:T9) -> 323392.65 | V9: =IF(INDEX(Escenarios!$K$12:$K$36,MATCH($A9,Escenarios!$A$12:$A$36,0))>0,$D9,0) -> 1385 | W9: =$E9*INDEX(Escenarios!$K$12:$K$36,MATCH($A9,Escenarios!$A$12:$A$36,0))*F9 -> 291053.39 | X9: =$E9*INDEX(Escenarios!$K$12:$K$36,MATCH($A9,Escenarios!$A$12:$A$36,0))*G9 -> 32339.265 | Y9: =$E9*INDEX(Escenarios!$K$12:$K$36,MATCH($A9,Escenarios!$A$12:$A$36,0))*H9 -> 0 | Z9: =$E9*INDEX(Escenarios!$K$12:$K$36,MATCH($A9,Escenarios!$A$12:$A$36,0))*I9 -> 0 | AA9: =SUM(W9:Z9) -> 323392.65 | AB9: =IF(INDEX(Escenarios!$L$12:$L$36,MATCH($A9,Escenarios!$A$12:$A$36,0))>0,$D9,0) -> 1385 | AC9: =$E9*INDEX(Escenarios!$L$12:$L$36,MATCH($A9,Escenarios!$A$12:$A$36,0))*F9 -> 291053.39 | AD9: =$E9*INDEX(Escenarios!$L$12:$L$36,MATCH($A9,Escenarios!$A$12:$A$36,0))*G9 -> 32339.265 | AE9: =$E9*INDEX(Escenarios!$L$12:$L$36,MATCH($A9,Escenarios!$A$12:$A$36,0))*H9 -> 0 | AF9: =$E9*INDEX(Escenarios!$L$12:$L$36,MATCH($A9,Escenarios!$A$12:$A$36,0))*I9 -> 0 | AG9: =SUM(AC9:AF9) -> 323392.65
A10: S17 | B10: ALARP (Optioneering) Study | C10: =INDEX(Escenarios!$D$12:$D$36,MATCH($A10,Escenarios!$A$12:$A$36,0)) -> Compartido | D10: =SUMIFS(Datos!$H$5:$H$291,Datos!$E$5:$E$291,$A10,Datos!$F$5:$F$291,"S3") -> 650 | E10: =SUMIFS(Datos!$J$5:$J$291,Datos!$E$5:$E$291,$A10,Datos!$F$5:$F$291,"S3") -> 151656.23 | F10: =INDEX(Escenarios!$E$12:$E$36,MATCH($A10,Escenarios!$A$12:$A$36,0)) -> 0.9 | G10: =INDEX(Escenarios!$F$12:$F$36,MATCH($A10,Escenarios!$A$12:$A$36,0)) -> 0.1 | H10: =INDEX(Escenarios!$G$12:$G$36,MATCH($A10,Escenarios!$A$12:$A$36,0)) -> 0 | I10: =INDEX(Escenarios!$H$12:$H$36,MATCH($A10,Escenarios!$A$12:$A$36,0)) -> 0 | J10: =IF(INDEX(Escenarios!$I$12:$I$36,MATCH($A10,Escenarios!$A$12:$A$36,0))>0,$D10,0) -> 650 | K10: =$E10*INDEX(Escenarios!$I$12:$I$36,MATCH($A10,Escenarios!$A$12:$A$36,0))*F10 -> 136490.6 | L10: =$E10*INDEX(Escenarios!$I$12:$I$36,MATCH($A10,Escenarios!$A$12:$A$36,0))*G10 -> 15165.622 | M10: =$E10*INDEX(Escenarios!$I$12:$I$36,MATCH($A10,Escenarios!$A$12:$A$36,0))*H10 -> 0 | N10: =$E10*INDEX(Escenarios!$I$12:$I$36,MATCH($A10,Escenarios!$A$12:$A$36,0))*I10 -> 0 | O10: =SUM(K10:N10) -> 151656.23 | P10: =IF(INDEX(Escenarios!$J$12:$J$36,MATCH($A10,Escenarios!$A$12:$A$36,0))>0,$D10,0) -> 650 | Q10: =$E10*INDEX(Escenarios!$J$12:$J$36,MATCH($A10,Escenarios!$A$12:$A$36,0))*F10 -> 136490.6 | R10: =$E10*INDEX(Escenarios!$J$12:$J$36,MATCH($A10,Escenarios!$A$12:$A$36,0))*G10 -> 15165.622 | S10: =$E10*INDEX(Escenarios!$J$12:$J$36,MATCH($A10,Escenarios!$A$12:$A$36,0))*H10 -> 0 | T10: =$E10*INDEX(Escenarios!$J$12:$J$36,MATCH($A10,Escenarios!$A$12:$A$36,0))*I10 -> 0 | U10: =SUM(Q10:T10) -> 151656.23 | V10: =IF(INDEX(Escenarios!$K$12:$K$36,MATCH($A10,Escenarios!$A$12:$A$36,0))>0,$D10,0) -> 650 | W10: =$E10*INDEX(Escenarios!$K$12:$K$36,MATCH($A10,Escenarios!$A$12:$A$36,0))*F10 -> 136490.6 | X10: =$E10*INDEX(Escenarios!$K$12:$K$36,MATCH($A10,Escenarios!$A$12:$A$36,0))*G10 -> 15165.622 | Y10: =$E10*INDEX(Escenarios!$K$12:$K$36,MATCH($A10,Escenarios!$A$12:$A$36,0))*H10 -> 0 | Z10: =$E10*INDEX(Escenarios!$K$12:$K$36,MATCH($A10,Escenarios!$A$12:$A$36,0))*I10 -> 0 | AA10: =SUM(W10:Z10) -> 151656.23 | AB10: =IF(INDEX(Escenarios!$L$12:$L$36,MATCH($A10,Escenarios!$A$12:$A$36,0))>0,$D10,0) -> 650 | AC10: =$E10*INDEX(Escenarios!$L$12:$L$36,MATCH($A10,Escenarios!$A$12:$A$36,0))*F10 -> 136490.6 | AD10: =$E10*INDEX(Escenarios!$L$12:$L$36,MATCH($A10,Escenarios!$A$12:$A$36,0))*G10 -> 15165.622 | AE10: =$E10*INDEX(Escenarios!$L$12:$L$36,MATCH($A10,Escenarios!$A$12:$A$36,0))*H10 -> 0 | AF10: =$E10*INDEX(Escenarios!$L$12:$L$36,MATCH($A10,Escenarios!$A$12:$A$36,0))*I10 -> 0 | AG10: =SUM(AC10:AF10) -> 151656.23
A11: S21 | B11: Radiological Shielding Basis of Design | C11: =INDEX(Escenarios!$D$12:$D$36,MATCH($A11,Escenarios!$A$12:$A$36,0)) -> IDOM | D11: =SUMIFS(Datos!$H$5:$H$291,Datos!$E$5:$E$291,$A11,Datos!$F$5:$F$291,"S3") -> 385 | E11: =SUMIFS(Datos!$J$5:$J$291,Datos!$E$5:$E$291,$A11,Datos!$F$5:$F$291,"S3") -> 89229 | F11: =INDEX(Escenarios!$E$12:$E$36,MATCH($A11,Escenarios!$A$12:$A$36,0)) -> 1 | G11: =INDEX(Escenarios!$F$12:$F$36,MATCH($A11,Escenarios!$A$12:$A$36,0)) -> 0 | H11: =INDEX(Escenarios!$G$12:$G$36,MATCH($A11,Escenarios!$A$12:$A$36,0)) -> 0 | I11: =INDEX(Escenarios!$H$12:$H$36,MATCH($A11,Escenarios!$A$12:$A$36,0)) -> 0 | J11: =IF(INDEX(Escenarios!$I$12:$I$36,MATCH($A11,Escenarios!$A$12:$A$36,0))>0,$D11,0) -> 385 | K11: =$E11*INDEX(Escenarios!$I$12:$I$36,MATCH($A11,Escenarios!$A$12:$A$36,0))*F11 -> 89229 | L11: =$E11*INDEX(Escenarios!$I$12:$I$36,MATCH($A11,Escenarios!$A$12:$A$36,0))*G11 -> 0 | M11: =$E11*INDEX(Escenarios!$I$12:$I$36,MATCH($A11,Escenarios!$A$12:$A$36,0))*H11 -> 0 | N11: =$E11*INDEX(Escenarios!$I$12:$I$36,MATCH($A11,Escenarios!$A$12:$A$36,0))*I11 -> 0 | O11: =SUM(K11:N11) -> 89229 | P11: =IF(INDEX(Escenarios!$J$12:$J$36,MATCH($A11,Escenarios!$A$12:$A$36,0))>0,$D11,0) -> 385 | Q11: =$E11*INDEX(Escenarios!$J$12:$J$36,MATCH($A11,Escenarios!$A$12:$A$36,0))*F11 -> 89229 | R11: =$E11*INDEX(Escenarios!$J$12:$J$36,MATCH($A11,Escenarios!$A$12:$A$36,0))*G11 -> 0 | S11: =$E11*INDEX(Escenarios!$J$12:$J$36,MATCH($A11,Escenarios!$A$12:$A$36,0))*H11 -> 0 | T11: =$E11*INDEX(Escenarios!$J$12:$J$36,MATCH($A11,Escenarios!$A$12:$A$36,0))*I11 -> 0 | U11: =SUM(Q11:T11) -> 89229 | V11: =IF(INDEX(Escenarios!$K$12:$K$36,MATCH($A11,Escenarios!$A$12:$A$36,0))>0,$D11,0) -> 385 | W11: =$E11*INDEX(Escenarios!$K$12:$K$36,MATCH($A11,Escenarios!$A$12:$A$36,0))*F11 -> 89229 | X11: =$E11*INDEX(Escenarios!$K$12:$K$36,MATCH($A11,Escenarios!$A$12:$A$36,0))*G11 -> 0 | Y11: =$E11*INDEX(Escenarios!$K$12:$K$36,MATCH($A11,Escenarios!$A$12:$A$36,0))*H11 -> 0 | Z11: =$E11*INDEX(Escenarios!$K$12:$K$36,MATCH($A11,Escenarios!$A$12:$A$36,0))*I11 -> 0 | AA11: =SUM(W11:Z11) -> 89229 | AB11: =IF(INDEX(Escenarios!$L$12:$L$36,MATCH($A11,Escenarios!$A$12:$A$36,0))>0,$D11,0) -> 385 | AC11: =$E11*INDEX(Escenarios!$L$12:$L$36,MATCH($A11,Escenarios!$A$12:$A$36,0))*F11 -> 89229 | AD11: =$E11*INDEX(Escenarios!$L$12:$L$36,MATCH($A11,Escenarios!$A$12:$A$36,0))*G11 -> 0 | AE11: =$E11*INDEX(Escenarios!$L$12:$L$36,MATCH($A11,Escenarios!$A$12:$A$36,0))*H11 -> 0 | AF11: =$E11*INDEX(Escenarios!$L$12:$L$36,MATCH($A11,Escenarios!$A$12:$A$36,0))*I11 -> 0 | AG11: =SUM(AC11:AF11) -> 89229
A12: S22 | B12: Radiological Shielding Assessment | C12: =INDEX(Escenarios!$D$12:$D$36,MATCH($A12,Escenarios!$A$12:$A$36,0)) -> IDOM | D12: =SUMIFS(Datos!$H$5:$H$291,Datos!$E$5:$E$291,$A12,Datos!$F$5:$F$291,"S3") -> 675 | E12: =SUMIFS(Datos!$J$5:$J$291,Datos!$E$5:$E$291,$A12,Datos!$F$5:$F$291,"S3") -> 155044.58 | F12: =INDEX(Escenarios!$E$12:$E$36,MATCH($A12,Escenarios!$A$12:$A$36,0)) -> 1 | G12: =INDEX(Escenarios!$F$12:$F$36,MATCH($A12,Escenarios!$A$12:$A$36,0)) -> 0 | H12: =INDEX(Escenarios!$G$12:$G$36,MATCH($A12,Escenarios!$A$12:$A$36,0)) -> 0 | I12: =INDEX(Escenarios!$H$12:$H$36,MATCH($A12,Escenarios!$A$12:$A$36,0)) -> 0 | J12: =IF(INDEX(Escenarios!$I$12:$I$36,MATCH($A12,Escenarios!$A$12:$A$36,0))>0,$D12,0) -> 675 | K12: =$E12*INDEX(Escenarios!$I$12:$I$36,MATCH($A12,Escenarios!$A$12:$A$36,0))*F12 -> 155044.58 | L12: =$E12*INDEX(Escenarios!$I$12:$I$36,MATCH($A12,Escenarios!$A$12:$A$36,0))*G12 -> 0 | M12: =$E12*INDEX(Escenarios!$I$12:$I$36,MATCH($A12,Escenarios!$A$12:$A$36,0))*H12 -> 0 | N12: =$E12*INDEX(Escenarios!$I$12:$I$36,MATCH($A12,Escenarios!$A$12:$A$36,0))*I12 -> 0 | O12: =SUM(K12:N12) -> 155044.58 | P12: =IF(INDEX(Escenarios!$J$12:$J$36,MATCH($A12,Escenarios!$A$12:$A$36,0))>0,$D12,0) -> 675 | Q12: =$E12*INDEX(Escenarios!$J$12:$J$36,MATCH($A12,Escenarios!$A$12:$A$36,0))*F12 -> 155044.58 | R12: =$E12*INDEX(Escenarios!$J$12:$J$36,MATCH($A12,Escenarios!$A$12:$A$36,0))*G12 -> 0 | S12: =$E12*INDEX(Escenarios!$J$12:$J$36,MATCH($A12,Escenarios!$A$12:$A$36,0))*H12 -> 0 | T12: =$E12*INDEX(Escenarios!$J$12:$J$36,MATCH($A12,Escenarios!$A$12:$A$36,0))*I12 -> 0 | U12: =SUM(Q12:T12) -> 155044.58 | V12: =IF(INDEX(Escenarios!$K$12:$K$36,MATCH($A12,Escenarios!$A$12:$A$36,0))>0,$D12,0) -> 675 | W12: =$E12*INDEX(Escenarios!$K$12:$K$36,MATCH($A12,Escenarios!$A$12:$A$36,0))*F12 -> 155044.58 | X12: =$E12*INDEX(Escenarios!$K$12:$K$36,MATCH($A12,Escenarios!$A$12:$A$36,0))*G12 -> 0 | Y12: =$E12*INDEX(Escenarios!$K$12:$K$36,MATCH($A12,Escenarios!$A$12:$A$36,0))*H12 -> 0 | Z12: =$E12*INDEX(Escenarios!$K$12:$K$36,MATCH($A12,Escenarios!$A$12:$A$36,0))*I12 -> 0 | AA12: =SUM(W12:Z12) -> 155044.58 | AB12: =IF(INDEX(Escenarios!$L$12:$L$36,MATCH($A12,Escenarios!$A$12:$A$36,0))>0,$D12,0) -> 675 | AC12: =$E12*INDEX(Escenarios!$L$12:$L$36,MATCH($A12,Escenarios!$A$12:$A$36,0))*F12 -> 155044.58 | AD12: =$E12*INDEX(Escenarios!$L$12:$L$36,MATCH($A12,Escenarios!$A$12:$A$36,0))*G12 -> 0 | AE12: =$E12*INDEX(Escenarios!$L$12:$L$36,MATCH($A12,Escenarios!$A$12:$A$36,0))*H12 -> 0 | AF12: =$E12*INDEX(Escenarios!$L$12:$L$36,MATCH($A12,Escenarios!$A$12:$A$36,0))*I12 -> 0 | AG12: =SUM(AC12:AF12) -> 155044.58
A13: S23 | B13: Radiological Contamination Control Strategy | C13: =INDEX(Escenarios!$D$12:$D$36,MATCH($A13,Escenarios!$A$12:$A$36,0)) -> Compartido | D13: =SUMIFS(Datos!$H$5:$H$291,Datos!$E$5:$E$291,$A13,Datos!$F$5:$F$291,"S3") -> 480 | E13: =SUMIFS(Datos!$J$5:$J$291,Datos!$E$5:$E$291,$A13,Datos!$F$5:$F$291,"S3") -> 110536.65 | F13: =INDEX(Escenarios!$E$12:$E$36,MATCH($A13,Escenarios!$A$12:$A$36,0)) -> 0.9 | G13: =INDEX(Escenarios!$F$12:$F$36,MATCH($A13,Escenarios!$A$12:$A$36,0)) -> 0.1 | H13: =INDEX(Escenarios!$G$12:$G$36,MATCH($A13,Escenarios!$A$12:$A$36,0)) -> 0 | I13: =INDEX(Escenarios!$H$12:$H$36,MATCH($A13,Escenarios!$A$12:$A$36,0)) -> 0 | J13: =IF(INDEX(Escenarios!$I$12:$I$36,MATCH($A13,Escenarios!$A$12:$A$36,0))>0,$D13,0) -> 480 | K13: =$E13*INDEX(Escenarios!$I$12:$I$36,MATCH($A13,Escenarios!$A$12:$A$36,0))*F13 -> 99482.985 | L13: =$E13*INDEX(Escenarios!$I$12:$I$36,MATCH($A13,Escenarios!$A$12:$A$36,0))*G13 -> 11053.665 | M13: =$E13*INDEX(Escenarios!$I$12:$I$36,MATCH($A13,Escenarios!$A$12:$A$36,0))*H13 -> 0 | N13: =$E13*INDEX(Escenarios!$I$12:$I$36,MATCH($A13,Escenarios!$A$12:$A$36,0))*I13 -> 0 | O13: =SUM(K13:N13) -> 110536.65 | P13: =IF(INDEX(Escenarios!$J$12:$J$36,MATCH($A13,Escenarios!$A$12:$A$36,0))>0,$D13,0) -> 480 | Q13: =$E13*INDEX(Escenarios!$J$12:$J$36,MATCH($A13,Escenarios!$A$12:$A$36,0))*F13 -> 99482.985 | R13: =$E13*INDEX(Escenarios!$J$12:$J$36,MATCH($A13,Escenarios!$A$12:$A$36,0))*G13 -> 11053.665 | S13: =$E13*INDEX(Escenarios!$J$12:$J$36,MATCH($A13,Escenarios!$A$12:$A$36,0))*H13 -> 0 | T13: =$E13*INDEX(Escenarios!$J$12:$J$36,MATCH($A13,Escenarios!$A$12:$A$36,0))*I13 -> 0 | U13: =SUM(Q13:T13) -> 110536.65 | V13: =IF(INDEX(Escenarios!$K$12:$K$36,MATCH($A13,Escenarios!$A$12:$A$36,0))>0,$D13,0) -> 480 | W13: =$E13*INDEX(Escenarios!$K$12:$K$36,MATCH($A13,Escenarios!$A$12:$A$36,0))*F13 -> 99482.985 | X13: =$E13*INDEX(Escenarios!$K$12:$K$36,MATCH($A13,Escenarios!$A$12:$A$36,0))*G13 -> 11053.665 | Y13: =$E13*INDEX(Escenarios!$K$12:$K$36,MATCH($A13,Escenarios!$A$12:$A$36,0))*H13 -> 0 | Z13: =$E13*INDEX(Escenarios!$K$12:$K$36,MATCH($A13,Escenarios!$A$12:$A$36,0))*I13 -> 0 | AA13: =SUM(W13:Z13) -> 110536.65 | AB13: =IF(INDEX(Escenarios!$L$12:$L$36,MATCH($A13,Escenarios!$A$12:$A$36,0))>0,$D13,0) -> 480 | AC13: =$E13*INDEX(Escenarios!$L$12:$L$36,MATCH($A13,Escenarios!$A$12:$A$36,0))*F13 -> 99482.985 | AD13: =$E13*INDEX(Escenarios!$L$12:$L$36,MATCH($A13,Escenarios!$A$12:$A$36,0))*G13 -> 11053.665 | AE13: =$E13*INDEX(Escenarios!$L$12:$L$36,MATCH($A13,Escenarios!$A$12:$A$36,0))*H13 -> 0 | AF13: =$E13*INDEX(Escenarios!$L$12:$L$36,MATCH($A13,Escenarios!$A$12:$A$36,0))*I13 -> 0 | AG13: =SUM(AC13:AF13) -> 110536.65
A14: S24 | B14: Radiological Classification of Areas (RCA) | C14: =INDEX(Escenarios!$D$12:$D$36,MATCH($A14,Escenarios!$A$12:$A$36,0)) -> IDOM | D14: =SUMIFS(Datos!$H$5:$H$291,Datos!$E$5:$E$291,$A14,Datos!$F$5:$F$291,"S3") -> 490 | E14: =SUMIFS(Datos!$J$5:$J$291,Datos!$E$5:$E$291,$A14,Datos!$F$5:$F$291,"S3") -> 112300.65 | F14: =INDEX(Escenarios!$E$12:$E$36,MATCH($A14,Escenarios!$A$12:$A$36,0)) -> 1 | G14: =INDEX(Escenarios!$F$12:$F$36,MATCH($A14,Escenarios!$A$12:$A$36,0)) -> 0 | H14: =INDEX(Escenarios!$G$12:$G$36,MATCH($A14,Escenarios!$A$12:$A$36,0)) -> 0 | I14: =INDEX(Escenarios!$H$12:$H$36,MATCH($A14,Escenarios!$A$12:$A$36,0)) -> 0 | J14: =IF(INDEX(Escenarios!$I$12:$I$36,MATCH($A14,Escenarios!$A$12:$A$36,0))>0,$D14,0) -> 490 | K14: =$E14*INDEX(Escenarios!$I$12:$I$36,MATCH($A14,Escenarios!$A$12:$A$36,0))*F14 -> 112300.65 | L14: =$E14*INDEX(Escenarios!$I$12:$I$36,MATCH($A14,Escenarios!$A$12:$A$36,0))*G14 -> 0 | M14: =$E14*INDEX(Escenarios!$I$12:$I$36,MATCH($A14,Escenarios!$A$12:$A$36,0))*H14 -> 0 | N14: =$E14*INDEX(Escenarios!$I$12:$I$36,MATCH($A14,Escenarios!$A$12:$A$36,0))*I14 -> 0 | O14: =SUM(K14:N14) -> 112300.65 | P14: =IF(INDEX(Escenarios!$J$12:$J$36,MATCH($A14,Escenarios!$A$12:$A$36,0))>0,$D14,0) -> 490 | Q14: =$E14*INDEX(Escenarios!$J$12:$J$36,MATCH($A14,Escenarios!$A$12:$A$36,0))*F14 -> 112300.65 | R14: =$E14*INDEX(Escenarios!$J$12:$J$36,MATCH($A14,Escenarios!$A$12:$A$36,0))*G14 -> 0 | S14: =$E14*INDEX(Escenarios!$J$12:$J$36,MATCH($A14,Escenarios!$A$12:$A$36,0))*H14 -> 0 | T14: =$E14*INDEX(Escenarios!$J$12:$J$36,MATCH($A14,Escenarios!$A$12:$A$36,0))*I14 -> 0 | U14: =SUM(Q14:T14) -> 112300.65 | V14: =IF(INDEX(Escenarios!$K$12:$K$36,MATCH($A14,Escenarios!$A$12:$A$36,0))>0,$D14,0) -> 490 | W14: =$E14*INDEX(Escenarios!$K$12:$K$36,MATCH($A14,Escenarios!$A$12:$A$36,0))*F14 -> 112300.65 | X14: =$E14*INDEX(Escenarios!$K$12:$K$36,MATCH($A14,Escenarios!$A$12:$A$36,0))*G14 -> 0 | Y14: =$E14*INDEX(Escenarios!$K$12:$K$36,MATCH($A14,Escenarios!$A$12:$A$36,0))*H14 -> 0 | Z14: =$E14*INDEX(Escenarios!$K$12:$K$36,MATCH($A14,Escenarios!$A$12:$A$36,0))*I14 -> 0 | AA14: =SUM(W14:Z14) -> 112300.65 | AB14: =IF(INDEX(Escenarios!$L$12:$L$36,MATCH($A14,Escenarios!$A$12:$A$36,0))>0,$D14,0) -> 490 | AC14: =$E14*INDEX(Escenarios!$L$12:$L$36,MATCH($A14,Escenarios!$A$12:$A$36,0))*F14 -> 112300.65 | AD14: =$E14*INDEX(Escenarios!$L$12:$L$36,MATCH($A14,Escenarios!$A$12:$A$36,0))*G14 -> 0 | AE14: =$E14*INDEX(Escenarios!$L$12:$L$36,MATCH($A14,Escenarios!$A$12:$A$36,0))*H14 -> 0 | AF14: =$E14*INDEX(Escenarios!$L$12:$L$36,MATCH($A14,Escenarios!$A$12:$A$36,0))*I14 -> 0 | AG14: =SUM(AC14:AF14) -> 112300.65
