Workbook

Sheet Executive Summary
B1: NMMP — Nuclear and Radiological Scope (PSC002818)
B2: Executive summary of price reduction options
B3: ="Basis for every scenario: Stage 2 rework allowance released ("&TEXT(Assumptions!$C$6,"0%")&" instead of "&TEXT(Assumptions!$C$5,"0%")&", all deliverables assumed right first time) and a "&TEXT(Assumptions!$C$7,"0.0%")&" commercial discount on IDOM's scope. Figures in A$, excluding GST." -> Basis for every scenario: Stage 2 rework allowance released (0% instead of 35%, all deliverables assumed right first time) and a 4.0% commercial discount on IDOM's scope. Figures in A$, excluding GST.
B5: 1 · Offer price by scenario
B6: Scenario | C6: Total offer price | D6: Reduction A$ | E6: Reduction % | F6: Lump sum S1–S3 | G6: Stages 1–5 | H6: Provisional S4–S7 | I6: Synertec benchmark | J6: Deviation vs benchmark A$ | K6: Deviation vs benchmark %
B7: Original offer (as submitted) | C7: ='Scenario Detail'!G6 -> 7530724 | D7: =$C$7-C7 -> 0 | E7: =IF($C$7=0,0,D7/$C$7) -> 0 | F7: ='Scenario Detail'!G16 -> 2537245.7 | G7: ='Scenario Detail'!G46 -> 6261739.2 | H7: ='Scenario Detail'!G26+'Scenario Detail'!G36 -> 4993478.3 | I7: ='Scenario Detail'!J6 -> 3809000 | J7: =C7-I7 -> 3721724 | K7: =IF(C7=0,0,(I7-C7)/C7) -> -0.49420534
B8: Scenario 1 · Base offer | C8: ='Scenario Detail'!G7 -> 7162862.6 | D8: =$C$7-C8 -> 367861.36 | E8: =IF($C$7=0,0,D8/$C$7) -> 0.048848074 | F8: ='Scenario Detail'!G17 -> 2328401.4 | G8: ='Scenario Detail'!G47 -> 5933727 | H8: ='Scenario Detail'!G27+'Scenario Detail'!G37 -> 4834461.2 | I8: ='Scenario Detail'!J7 -> 3809000 | J8: =C8-I8 -> 3353862.6 | K8: =IF(C8=0,0,(I8-C8)/C8) -> -0.46822937
B9: Scenario 2 · Without Plan Safe HF tasks | C9: ='Scenario Detail'!G8 -> 5941147.1 | D9: =$C$7-C9 -> 1589576.9 | E9: =IF($C$7=0,0,D9/$C$7) -> 0.21107889 | F9: ='Scenario Detail'!G18 -> 1871661.4 | G9: ='Scenario Detail'!G48 -> 4915349.2 | H9: ='Scenario Detail'!G28+'Scenario Detail'!G38 -> 4069485.7 | I9: ='Scenario Detail'!J8 -> 3809000 | J9: =C9-I9 -> 2132147.1 | K9: =IF(C9=0,0,(I9-C9)/C9) -> -0.35887802
B10: Scenario 3 · Without Plan Safe HF tasks and SSC | C10: ='Scenario Detail'!G9 -> 4376618.9 | D10: =$C$7-C10 -> 3154105.1 | E10: =IF($C$7=0,0,D10/$C$7) -> 0.41883159 | F10: ='Scenario Detail'!G19 -> 1533068.1 | G10: ='Scenario Detail'!G49 -> 3737301.9 | H10: ='Scenario Detail'!G29+'Scenario Detail'!G39 -> 2843550.9 | I10: ='Scenario Detail'!J9 -> 3809000 | J10: =C10-I10 -> 567618.92 | K10: =IF(C10=0,0,(I10-C10)/C10) -> -0.12969348
B11: Scenario 4 · Without SSC, Plan Safe HF tasks at reduced price | C11: ='Scenario Detail'!G10 -> 4987476.7 | D11: =$C$7-C11 -> 2543247.3 | E11: =IF($C$7=0,0,D11/$C$7) -> 0.33771618 | F11: ='Scenario Detail'!G20 -> 1761438.1 | G11: ='Scenario Detail'!G50 -> 4246490.8 | H11: ='Scenario Detail'!G30+'Scenario Detail'!G40 -> 3226038.6 | I11: ='Scenario Detail'!J10 -> 3809000 | J11: =C11-I11 -> 1178476.7 | K11: =IF(C11=0,0,(I11-C11)/C11) -> -0.23628716
B12: Scenario 5 · Plan Safe as offered, without SSC | C12: ='Scenario Detail'!G11 -> 5598334.5 | D12: =$C$7-C12 -> 1932389.6 | E12: =IF($C$7=0,0,D12/$C$7) -> 0.25660077 | F12: ='Scenario Detail'!G21 -> 1989808.1 | G12: ='Scenario Detail'!G51 -> 4755679.7 | H12: ='Scenario Detail'!G31+'Scenario Detail'!G41 -> 3608526.4 | I12: ='Scenario Detail'!J11 -> 3809000 | J12: =C12-I12 -> 1789334.5 | K12: =IF(C12=0,0,(I12-C12)/C12) -> -0.31961907
B15: 2 · Who receives what (total offer, A$)
B16: Scenario | C16: IDOM | D16: Plan Safe | E16: INVAP | F16: Total | G16: IDOM share | H16: Hours
B17: =B7 -> Original offer (as submitted) | C17: ='Scenario Detail'!D6 -> 5858217.9 | D17: ='Scenario Detail'!E6 -> 1593670 | E17: ='Scenario Detail'!F6 -> 78836.1 | F17: =SUM(C17:E17) -> 7530724 | G17: =IF(F17=0,0,C17/F17) -> 0.77790899 | H17: ='Scenario Detail'!C6 -> 32722
B18: =B8 -> Scenario 1 · Base offer | C18: ='Scenario Detail'!D7 -> 5490356.5 | D18: ='Scenario Detail'!E7 -> 1593670 | E18: ='Scenario Detail'!F7 -> 78836.1 | F18: =SUM(C18:E18) -> 7162862.6 | G18: =IF(F18=0,0,C18/F18) -> 0.76650312 | H18: ='Scenario Detail'!C7 -> 32722
B19: =B9 -> Scenario 2 · Without Plan Safe HF tasks | C19: ='Scenario Detail'!D8 -> 5490356.5 | D19: ='Scenario Detail'!E8 -> 371954.47 | E19: ='Scenario Detail'!F8 -> 78836.1 | F19: =SUM(C19:E19) -> 5941147.1 | G19: =IF(F19=0,0,C19/F19) -> 0.92412399 | H19: ='Scenario Detail'!C8 -> 27415
B20: =B10 -> Scenario 3 · Without Plan Safe HF tasks and SSC | C20: ='Scenario Detail'!D9 -> 4003833.2 | D20: ='Scenario Detail'!E9 -> 293949.65 | E20: ='Scenario Detail'!F9 -> 78836.1 | F20: =SUM(C20:E20) -> 4376618.9 | G20: =IF(F20=0,0,C20/F20) -> 0.91482335 | H20: ='Scenario Detail'!C9 -> 20220
B21: =B11 -> Scenario 4 · Without SSC, Plan Safe HF tasks at reduced price | C21: ='Scenario Detail'!D10 -> 4003833.2 | D21: ='Scenario Detail'!E10 -> 904807.42 | E21: ='Scenario Detail'!F10 -> 78836.1 | F21: =SUM(C21:E21) -> 4987476.7 | G21: =IF(F21=0,0,C21/F21) -> 0.80277732 | H21: ='Scenario Detail'!C10 -> 25527
B22: =B12 -> Scenario 5 · Plan Safe as offered, without SSC | C22: ='Scenario Detail'!D11 -> 4003833.2 | D22: ='Scenario Detail'!E11 -> 1515665.2 | E22: ='Scenario Detail'!F11 -> 78836.1 | F22: =SUM(C22:E22) -> 5598334.5 | G22: =IF(F22=0,0,C22/F22) -> 0.71518292 | H22: ='Scenario Detail'!C11 -> 25527
B25: 3 · Key messages
B26: • | C26: ="Commercial measures alone (rework release and "&TEXT(Assumptions!$C$7,"0.0%")&" discount) bring the offer from A$"&TEXT(C7,"#,##0")&" to A$"&TEXT(C8,"#,##0")&", a reduction of "&TEXT(E8,"0.0%")&", without changing the scope." -> Commercial measures alone (rework release and 4.0% discount) bring the offer from A$7,530,724 to A$7,162,863, a reduction of 4.9%, without changing the scope.
B27: • | C27: ="Releasing the Stage 2 rework allowance is worth A$"&TEXT('Reduction Levers'!D6,"#,##0")&" and the commercial discount A$"&TEXT('Reduction Levers'!D7,"#,##0")&" in the base offer; both assume the design proceeds right first time on a stable basis of design." -> Releasing the Stage 2 rework allowance is worth A$139,097 and the commercial discount A$228,765 in the base offer; both assume the design proceeds right first time on a stable basis of design.
B28: • | C28: ="The largest further reductions require scope changes to be agreed with ANSTO: removing the SSC group (S26–S29) saves up to A$"&TEXT(MAX('Reduction Levers'!D9:H9),"#,##0")&" and removing Plan Safe's HF deliverables up to A$"&TEXT(MAX('Reduction Levers'!D8:H8),"#,##0")&"." -> The largest further reductions require scope changes to be agreed with ANSTO: removing the SSC group (S26–S29) saves up to A$1,652,324 and removing Plan Safe's HF deliverables up to A$1,221,716.
B29: • | C29: ="Against the Synertec benchmark of A$"&TEXT(I7,"#,##0")&", the gap falls from "&TEXT(K7,"0.0%")&" in the original offer to between "&TEXT(MAX(K8:K12),"0.0%")&" and "&TEXT(MIN(K8:K12),"0.0%")&" across the scenarios; the lump sum S1–S3 is the block closest to the benchmark (see Synertec Benchmark tab)." -> Against the Synertec benchmark of A$3,809,000, the gap falls from -49.4% in the original offer to between -13.0% and -46.8% across the scenarios; the lump sum S1–S3 is the block closest to the benchmark (see Synertec Benchmark tab).
B30: • | C30: =IF(Assumptions!$C$10="Yes","Deliverable S1 is priced as a two-week single issue (A$"&TEXT(Assumptions!$C$12,"#,##0")&"); see the justification and its limits in the Reduction Levers tab.","Pricing deliverable S1 as a two-week single issue (A$"&TEXT(Assumptions!$C$12,"#,##0")&") is available as an optional lever worth about A$"&TEXT(SUM(Calculation!M6:S6)-Assumptions!$C$12,"#,##0")&"; it is not included in these figures.") -> Pricing deliverable S1 as a two-week single issue (A$38,675) is available as an optional lever worth about A$393,744; it is not included in these figures.
B32: Tabs: Reduction Levers (value and justification of each lever) · Scenario Detail (by price block and company) · Synertec Benchmark (by stage) · Assumptions (inputs) · Calculation and Data (engine and source).

Sheet Reduction Levers
B1: Reduction levers and justification
B2: Reduction in A$ against the original offer, by lever and scenario. Positive = price reduction. Levers are applied in this order: scope (scenario), deliverable S1 option, Stage 2 rework release, commercial discount.
B4: A · Total offer (Stages 1–7)
B5: Lever | C5: Type | D5: Sc. 1 Base offer | E5: Sc. 2 Without Plan Safe HF tasks | F5: Sc. 3 Without Plan Safe HF tasks and SSC | G5: Sc. 4 Without SSC, Plan Safe HF tasks at reduced price | H5: Sc. 5 Plan Safe as offered, without SSC
B6: Stage 2 rework allowance released | C6: Commercial (all) | D6: =-SUM(Calculation!M56:S56) -> 139096.5 | E6: =-SUM(Calculation!M73:S73) -> 139096.5 | F6: =-SUM(Calculation!M90:S90) -> 113239.07 | G6: =-SUM(Calculation!M107:S107) -> 113239.07 | H6: =-SUM(Calculation!M124:S124) -> 113239.07
B7: Commercial discount on IDOM's scope | C7: Commercial (all) | D7: =-SUM(Calculation!M57:S57) -> 228764.86 | E7: =-SUM(Calculation!M74:S74) -> 228764.86 | F7: =-SUM(Calculation!M91:S91) -> 166826.38 | G7: =-SUM(Calculation!M108:S108) -> 166826.38 | H7: =-SUM(Calculation!M125:S125) -> 166826.38
B8: Plan Safe human factors deliverables | C8: Scope | D8: =SUMPRODUCT((Calculation!$D$5:$D$29="Plan Safe task")*Calculation!$AE$5:$AE$29*(1-Calculation!$H$5:$H$29)) -> 0 | E8: =SUMPRODUCT((Calculation!$D$5:$D$29="Plan Safe task")*Calculation!$AE$5:$AE$29*(1-Calculation!$I$5:$I$29)) -> 1221715.5 | F8: =SUMPRODUCT((Calculation!$D$5:$D$29="Plan Safe task")*Calculation!$AE$5:$AE$29*(1-Calculation!$J$5:$J$29)) -> 1221715.5 | G8: =SUMPRODUCT((Calculation!$D$5:$D$29="Plan Safe task")*Calculation!$AE$5:$AE$29*(1-Calculation!$K$5:$K$29)) -> 610857.77 | H8: =SUMPRODUCT((Calculation!$D$5:$D$29="Plan Safe task")*Calculation!$AE$5:$AE$29*(1-Calculation!$L$5:$L$29)) -> 0
B9: SSC group (S26, S27, S28, S29) | C9: Scope | D9: =SUMPRODUCT((Calculation!$D$5:$D$29="SSC")*Calculation!$AE$5:$AE$29*(1-Calculation!$H$5:$H$29)) -> 0 | E9: =SUMPRODUCT((Calculation!$D$5:$D$29="SSC")*Calculation!$AE$5:$AE$29*(1-Calculation!$I$5:$I$29)) -> 0 | F9: =SUMPRODUCT((Calculation!$D$5:$D$29="SSC")*Calculation!$AE$5:$AE$29*(1-Calculation!$J$5:$J$29)) -> 1652324.1 | G9: =SUMPRODUCT((Calculation!$D$5:$D$29="SSC")*Calculation!$AE$5:$AE$29*(1-Calculation!$K$5:$K$29)) -> 1652324.1 | H9: =SUMPRODUCT((Calculation!$D$5:$D$29="SSC")*Calculation!$AE$5:$AE$29*(1-Calculation!$L$5:$L$29)) -> 1652324.1
B10: INVAP conceptual design verification | C10: Optional | D10: =SUMPRODUCT((Calculation!$D$5:$D$29="INVAP")*Calculation!$AE$5:$AE$29*(1-Calculation!$H$5:$H$29)) -> 0 | E10: =SUMPRODUCT((Calculation!$D$5:$D$29="INVAP")*Calculation!$AE$5:$AE$29*(1-Calculation!$I$5:$I$29)) -> 0 | F10: =SUMPRODUCT((Calculation!$D$5:$D$29="INVAP")*Calculation!$AE$5:$AE$29*(1-Calculation!$J$5:$J$29)) -> 0 | G10: =SUMPRODUCT((Calculation!$D$5:$D$29="INVAP")*Calculation!$AE$5:$AE$29*(1-Calculation!$K$5:$K$29)) -> 0 | H10: =SUMPRODUCT((Calculation!$D$5:$D$29="INVAP")*Calculation!$AE$5:$AE$29*(1-Calculation!$L$5:$L$29)) -> 0
B11: Deliverable S1 as a two-week single issue | C11: Optional | D11: =-(SUM(Calculation!M54:S54)+SUM(Calculation!M55:S55)) -> 0 | E11: =-(SUM(Calculation!M71:S71)+SUM(Calculation!M72:S72)) -> 0 | F11: =-(SUM(Calculation!M88:S88)+SUM(Calculation!M89:S89)) -> 0 | G11: =-(SUM(Calculation!M105:S105)+SUM(Calculation!M106:S106)) -> 0 | H11: =-(SUM(Calculation!M122:S122)+SUM(Calculation!M123:S123)) -> 0
B12: Total reduction | D12: =SUM(D6:D11) -> 367861.36 | E12: =SUM(E6:E11) -> 1589576.9 | F12: =SUM(F6:F11) -> 3154105.1 | G12: =SUM(G6:G11) -> 2543247.3 | H12: =SUM(H6:H11) -> 1932389.6
B13: Original offer price | D13: =SUM(Calculation!M44:S44) -> 7530724 | E13: =SUM(Calculation!M44:S44) -> 7530724 | F13: =SUM(Calculation!M44:S44) -> 7530724 | G13: =SUM(Calculation!M44:S44) -> 7530724 | H13: =SUM(Calculation!M44:S44) -> 7530724
B14: Resulting price | D14: =SUM(Calculation!M61:S61) -> 7162862.6 | E14: =SUM(Calculation!M78:S78) -> 5941147.1 | F14: =SUM(Calculation!M95:S95) -> 4376618.9 | G14: =SUM(Calculation!M112:S112) -> 4987476.7 | H14: =SUM(Calculation!M129:S129) -> 5598334.5
B15: % reduction | D15: =IF(D13=0,0,D12/D13) -> 0.048848074 | E15: =IF(E13=0,0,E12/E13) -> 0.21107889 | F15: =IF(F13=0,0,F12/F13) -> 0.41883159 | G15: =IF(G13=0,0,G12/G13) -> 0.33771618 | H15: =IF(H13=0,0,H12/H13) -> 0.25660077
B16: Check: original − resulting − total reduction | D16: =ROUND(D13-D14-D12,0) -> 0 | E16: =ROUND(E13-E14-E12,0) -> 0 | F16: =ROUND(F13-F14-F12,0) -> 0 | G16: =ROUND(G13-G14-G12,0) -> 0 | H16: =ROUND(H13-H14-H12,0) -> 0
B19: B · Lump sum (Stages 1–3)
B20: Lever | C20: Type | D20: Sc. 1 Base offer | E20: Sc. 2 Without Plan Safe HF tasks | F20: Sc. 3 Without Plan Safe HF tasks and SSC | G20: Sc. 4 Without SSC, Plan Safe HF tasks at reduced price | H20: Sc. 5 Plan Safe as offered, without SSC
B21: Stage 2 rework allowance released | C21: Commercial (all) | D21: =-SUM(Calculation!M56:O56) -> 139096.5 | E21: =-SUM(Calculation!M73:O73) -> 139096.5 | F21: =-SUM(Calculation!M90:O90) -> 113239.07 | G21: =-SUM(Calculation!M107:O107) -> 113239.07 | H21: =-SUM(Calculation!M124:O124) -> 113239.07
B22: Commercial discount on IDOM's scope | C22: Commercial (all) | D22: =-SUM(Calculation!M57:O57) -> 69747.783 | E22: =-SUM(Calculation!M74:O74) -> 69747.783 | F22: =-SUM(Calculation!M91:O91) -> 55974.917 | G22: =-SUM(Calculation!M108:O108) -> 55974.917 | H22: =-SUM(Calculation!M125:O125) -> 55974.917
B23: Plan Safe human factors deliverables | C23: Scope | D23: =SUMPRODUCT((Calculation!$D$5:$D$29="Plan Safe task")*Calculation!$AA$5:$AA$29*(1-Calculation!$H$5:$H$29)) -> 0 | E23: =SUMPRODUCT((Calculation!$D$5:$D$29="Plan Safe task")*Calculation!$AA$5:$AA$29*(1-Calculation!$I$5:$I$29)) -> 456740.03 | F23: =SUMPRODUCT((Calculation!$D$5:$D$29="Plan Safe task")*Calculation!$AA$5:$AA$29*(1-Calculation!$J$5:$J$29)) -> 456740.03 | G23: =SUMPRODUCT((Calculation!$D$5:$D$29="Plan Safe task")*Calculation!$AA$5:$AA$29*(1-Calculation!$K$5:$K$29)) -> 228370.01 | H23: =SUMPRODUCT((Calculation!$D$5:$D$29="Plan Safe task")*Calculation!$AA$5:$AA$29*(1-Calculation!$L$5:$L$29)) -> 0
B24: SSC group (S26, S27, S28, S29) | C24: Scope | D24: =SUMPRODUCT((Calculation!$D$5:$D$29="SSC")*Calculation!$AA$5:$AA$29*(1-Calculation!$H$5:$H$29)) -> 0 | E24: =SUMPRODUCT((Calculation!$D$5:$D$29="SSC")*Calculation!$AA$5:$AA$29*(1-Calculation!$I$5:$I$29)) -> 0 | F24: =SUMPRODUCT((Calculation!$D$5:$D$29="SSC")*Calculation!$AA$5:$AA$29*(1-Calculation!$J$5:$J$29)) -> 378223.65 | G24: =SUMPRODUCT((Calculation!$D$5:$D$29="SSC")*Calculation!$AA$5:$AA$29*(1-Calculation!$K$5:$K$29)) -> 378223.65 | H24: =SUMPRODUCT((Calculation!$D$5:$D$29="SSC")*Calculation!$AA$5:$AA$29*(1-Calculation!$L$5:$L$29)) -> 378223.65
B25: INVAP conceptual design verification | C25: Optional | D25: =SUMPRODUCT((Calculation!$D$5:$D$29="INVAP")*Calculation!$AA$5:$AA$29*(1-Calculation!$H$5:$H$29)) -> 0 | E25: =SUMPRODUCT((Calculation!$D$5:$D$29="INVAP")*Calculation!$AA$5:$AA$29*(1-Calculation!$I$5:$I$29)) -> 0 | F25: =SUMPRODUCT((Calculation!$D$5:$D$29="INVAP")*Calculation!$AA$5:$AA$29*(1-Calculation!$J$5:$J$29)) -> 0 | G25: =SUMPRODUCT((Calculation!$D$5:$D$29="INVAP")*Calculation!$AA$5:$AA$29*(1-Calculation!$K$5:$K$29)) -> 0 | H25: =SUMPRODUCT((Calculation!$D$5:$D$29="INVAP")*Calculation!$AA$5:$AA$29*(1-Calculation!$L$5:$L$29)) -> 0
B26: Deliverable S1 as a two-week single issue | C26: Optional | D26: =-(SUM(Calculation!M54:O54)+SUM(Calculation!M55:O55)) -> 0 | E26: =-(SUM(Calculation!M71:O71)+SUM(Calculation!M72:O72)) -> 0 | F26: =-(SUM(Calculation!M88:O88)+SUM(Calculation!M89:O89)) -> 0 | G26: =-(SUM(Calculation!M105:O105)+SUM(Calculation!M106:O106)) -> 0 | H26: =-(SUM(Calculation!M122:O122)+SUM(Calculation!M123:O123)) -> 0
B27: Total reduction | D27: =SUM(D21:D26) -> 208844.29 | E27: =SUM(E21:E26) -> 665584.31 | F27: =SUM(F21:F26) -> 1004177.7 | G27: =SUM(G21:G26) -> 775807.65 | H27: =SUM(H21:H26) -> 547437.64
B28: Original offer price | D28: =SUM(Calculation!M44:O44) -> 2537245.7 | E28: =SUM(Calculation!M44:O44) -> 2537245.7 | F28: =SUM(Calculation!M44:O44) -> 2537245.7 | G28: =SUM(Calculation!M44:O44) -> 2537245.7 | H28: =SUM(Calculation!M44:O44) -> 2537245.7
B29: Resulting price | D29: =SUM(Calculation!M61:O61) -> 2328401.4 | E29: =SUM(Calculation!M78:O78) -> 1871661.4 | F29: =SUM(Calculation!M95:O95) -> 1533068.1 | G29: =SUM(Calculation!M112:O112) -> 1761438.1 | H29: =SUM(Calculation!M129:O129) -> 1989808.1
B30: % reduction | D30: =IF(D28=0,0,D27/D28) -> 0.082311415 | E30: =IF(E28=0,0,E27/E28) -> 0.26232552 | F30: =IF(F28=0,0,F27/F28) -> 0.3957747 | G30: =IF(G28=0,0,G27/G28) -> 0.30576764 | H30: =IF(H28=0,0,H27/H28) -> 0.21576059
B31: Check: original − resulting − total reduction | D31: =ROUND(D28-D29-D27,0) -> 0 | E31: =ROUND(E28-E29-E27,0) -> 0 | F31: =ROUND(F28-F29-F27,0) -> 0 | G31: =ROUND(G28-G29-G27,0) -> 0 | H31: =ROUND(H28-H29-H27,0) -> 0
B34: C · Stages 1–5 (design to IFC)
B35: Lever | C35: Type | D35: Sc. 1 Base offer | E35: Sc. 2 Without Plan Safe HF tasks | F35: Sc. 3 Without Plan Safe HF tasks and SSC | G35: Sc. 4 Without SSC, Plan Safe HF tasks at reduced price | H35: Sc. 5 Plan Safe as offered, without SSC
B36: Stage 2 rework allowance released | C36: Commercial (all) | D36: =-SUM(Calculation!M56:Q56) -> 139096.5 | E36: =-SUM(Calculation!M73:Q73) -> 139096.5 | F36: =-SUM(Calculation!M90:Q90) -> 113239.07 | G36: =-SUM(Calculation!M107:Q107) -> 113239.07 | H36: =-SUM(Calculation!M124:Q124) -> 113239.07
B37: Commercial discount on IDOM's scope | C37: Commercial (all) | D37: =-SUM(Calculation!M57:Q57) -> 188915.63 | E37: =-SUM(Calculation!M74:Q74) -> 188915.63 | F37: =-SUM(Calculation!M91:Q91) -> 142162.77 | G37: =-SUM(Calculation!M108:Q108) -> 142162.77 | H37: =-SUM(Calculation!M125:Q125) -> 142162.77
B38: Plan Safe human factors deliverables | C38: Scope | D38: =SUMPRODUCT((Calculation!$D$5:$D$29="Plan Safe task")*Calculation!$AD$5:$AD$29*(1-Calculation!$H$5:$H$29)) -> 0 | E38: =SUMPRODUCT((Calculation!$D$5:$D$29="Plan Safe task")*Calculation!$AD$5:$AD$29*(1-Calculation!$I$5:$I$29)) -> 1018377.8 | F38: =SUMPRODUCT((Calculation!$D$5:$D$29="Plan Safe task")*Calculation!$AD$5:$AD$29*(1-Calculation!$J$5:$J$29)) -> 1018377.8 | G38: =SUMPRODUCT((Calculation!$D$5:$D$29="Plan Safe task")*Calculation!$AD$5:$AD$29*(1-Calculation!$K$5:$K$29)) -> 509188.89 | H38: =SUMPRODUCT((Calculation!$D$5:$D$29="Plan Safe task")*Calculation!$AD$5:$AD$29*(1-Calculation!$L$5:$L$29)) -> 0
B39: SSC group (S26, S27, S28, S29) | C39: Scope | D39: =SUMPRODUCT((Calculation!$D$5:$D$29="SSC")*Calculation!$AD$5:$AD$29*(1-Calculation!$H$5:$H$29)) -> 0 | E39: =SUMPRODUCT((Calculation!$D$5:$D$29="SSC")*Calculation!$AD$5:$AD$29*(1-Calculation!$I$5:$I$29)) -> 0 | F39: =SUMPRODUCT((Calculation!$D$5:$D$29="SSC")*Calculation!$AD$5:$AD$29*(1-Calculation!$J$5:$J$29)) -> 1250657.6 | G39: =SUMPRODUCT((Calculation!$D$5:$D$29="SSC")*Calculation!$AD$5:$AD$29*(1-Calculation!$K$5:$K$29)) -> 1250657.6 | H39: =SUMPRODUCT((Calculation!$D$5:$D$29="SSC")*Calculation!$AD$5:$AD$29*(1-Calculation!$L$5:$L$29)) -> 1250657.6
B40: INVAP conceptual design verification | C40: Optional | D40: =SUMPRODUCT((Calculation!$D$5:$D$29="INVAP")*Calculation!$AD$5:$AD$29*(1-Calculation!$H$5:$H$29)) -> 0 | E40: =SUMPRODUCT((Calculation!$D$5:$D$29="INVAP")*Calculation!$AD$5:$AD$29*(1-Calculation!$I$5:$I$29)) -> 0 | F40: =SUMPRODUCT((Calculation!$D$5:$D$29="INVAP")*Calculation!$AD$5:$AD$29*(1-Calculation!$J$5:$J$29)) -> 0 | G40: =SUMPRODUCT((Calculation!$D$5:$D$29="INVAP")*Calculation!$AD$5:$AD$29*(1-Calculation!$K$5:$K$29)) -> 0 | H40: =SUMPRODUCT((Calculation!$D$5:$D$29="INVAP")*Calculation!$AD$5:$AD$29*(1-Calculation!$L$5:$L$29)) -> 0
B41: Deliverable S1 as a two-week single issue | C41: Optional | D41: =-(SUM(Calculation!M54:Q54)+SUM(Calculation!M55:Q55)) -> 0 | E41: =-(SUM(Calculation!M71:Q71)+SUM(Calculation!M72:Q72)) -> 0 | F41: =-(SUM(Calculation!M88:Q88)+SUM(Calculation!M89:Q89)) -> 0 | G41: =-(SUM(Calculation!M105:Q105)+SUM(Calculation!M106:Q106)) -> 0 | H41: =-(SUM(Calculation!M122:Q122)+SUM(Calculation!M123:Q123)) -> 0
B42: Total reduction | D42: =SUM(D36:D41) -> 328012.13 | E42: =SUM(E36:E41) -> 1346389.9 | F42: =SUM(F36:F41) -> 2524437.2 | G42: =SUM(G36:G41) -> 2015248.3 | H42: =SUM(H36:H41) -> 1506059.5
B43: Original offer price | D43: =SUM(Calculation!M44:Q44) -> 6261739.2 | E43: =SUM(Calculation!M44:Q44) -> 6261739.2 | F43: =SUM(Calculation!M44:Q44) -> 6261739.2 | G43: =SUM(Calculation!M44:Q44) -> 6261739.2 | H43: =SUM(Calculation!M44:Q44) -> 6261739.2
B44: Resulting price | D44: =SUM(Calculation!M61:Q61) -> 5933727 | E44: =SUM(Calculation!M78:Q78) -> 4915349.2 | F44: =SUM(Calculation!M95:Q95) -> 3737301.9 | G44: =SUM(Calculation!M112:Q112) -> 4246490.8 | H44: =SUM(Calculation!M129:Q129) -> 4755679.7
B45: % reduction | D45: =IF(D43=0,0,D42/D43) -> 0.052383551 | E45: =IF(E43=0,0,E42/E43) -> 0.21501852 | F45: =IF(F43=0,0,F42/F43) -> 0.40315273 | G45: =IF(G43=0,0,G42/G43) -> 0.32183524 | H45: =IF(H43=0,0,H42/H43) -> 0.24051776
...

Sheet Scenario Detail
B1: Scenario detail by price block and company (A$)
B2: Every scenario includes the Stage 2 rework release and the commercial discount on IDOM. The reference row is the original offer with no adjustments.
B4: Total offer (Stages 1–7)
B5: Scenario | C5: Hours | D5: IDOM | E5: Plan Safe | F5: INVAP | G5: Total price | H5: Reduction A$ | I5: Reduction % | J5: Synertec benchmark | K5: Deviation A$ | L5: Deviation %
B6: Original offer (reference) | C6: =SUM(Calculation!M47:S47) -> 32722 | D6: =SUM(Calculation!M41:S41) -> 5858217.9 | E6: =SUM(Calculation!M42:S42) -> 1593670 | F6: =SUM(Calculation!M43:S43) -> 78836.1 | G6: =SUM(D6:F6) -> 7530724 | H6: =$G$6-G6 -> 0 | I6: =IF($G$6=0,0,H6/$G$6) -> 0 | J6: =('Synertec Benchmark'!$D$5+'Synertec Benchmark'!$D$6+'Synertec Benchmark'!$D$7+'Synertec Benchmark'!$D$8+'Synertec Benchmark'!$D$9+'Synertec Benchmark'!$D$10+'Synertec Benchmark'!$D$11) -> 3809000 | K6: =G6-J6 -> 3721724 | L6: =IF(G6=0,0,(J6-G6)/G6) -> -0.49420534
B7: Sc. 1 · Base offer | C7: =SUM(Calculation!M64:S64) -> 32722 | D7: =SUM(Calculation!M58:S58) -> 5490356.5 | E7: =SUM(Calculation!M59:S59) -> 1593670 | F7: =SUM(Calculation!M60:S60) -> 78836.1 | G7: =SUM(D7:F7) -> 7162862.6 | H7: =$G$6-G7 -> 367861.36 | I7: =IF($G$6=0,0,H7/$G$6) -> 0.048848074 | J7: =('Synertec Benchmark'!$D$5+'Synertec Benchmark'!$D$6+'Synertec Benchmark'!$D$7+'Synertec Benchmark'!$D$8+'Synertec Benchmark'!$D$9+'Synertec Benchmark'!$D$10+'Synertec Benchmark'!$D$11) -> 3809000 | K7: =G7-J7 -> 3353862.6 | L7: =IF(G7=0,0,(J7-G7)/G7) -> -0.46822937
B8: Sc. 2 · Without Plan Safe HF tasks | C8: =SUM(Calculation!M81:S81) -> 27415 | D8: =SUM(Calculation!M75:S75) -> 5490356.5 | E8: =SUM(Calculation!M76:S76) -> 371954.47 | F8: =SUM(Calculation!M77:S77) -> 78836.1 | G8: =SUM(D8:F8) -> 5941147.1 | H8: =$G$6-G8 -> 1589576.9 | I8: =IF($G$6=0,0,H8/$G$6) -> 0.21107889 | J8: =('Synertec Benchmark'!$D$5+'Synertec Benchmark'!$D$6+'Synertec Benchmark'!$D$7+'Synertec Benchmark'!$D$8+'Synertec Benchmark'!$D$9+'Synertec Benchmark'!$D$10+'Synertec Benchmark'!$D$11) -> 3809000 | K8: =G8-J8 -> 2132147.1 | L8: =IF(G8=0,0,(J8-G8)/G8) -> -0.35887802
B9: Sc. 3 · Without Plan Safe HF tasks and SSC | C9: =SUM(Calculation!M98:S98) -> 20220 | D9: =SUM(Calculation!M92:S92) -> 4003833.2 | E9: =SUM(Calculation!M93:S93) -> 293949.65 | F9: =SUM(Calculation!M94:S94) -> 78836.1 | G9: =SUM(D9:F9) -> 4376618.9 | H9: =$G$6-G9 -> 3154105.1 | I9: =IF($G$6=0,0,H9/$G$6) -> 0.41883159 | J9: =('Synertec Benchmark'!$D$5+'Synertec Benchmark'!$D$6+'Synertec Benchmark'!$D$7+'Synertec Benchmark'!$D$8+'Synertec Benchmark'!$D$9+'Synertec Benchmark'!$D$10+'Synertec Benchmark'!$D$11) -> 3809000 | K9: =G9-J9 -> 567618.92 | L9: =IF(G9=0,0,(J9-G9)/G9) -> -0.12969348
B10: Sc. 4 · Without SSC, Plan Safe HF tasks at reduced price | C10: =SUM(Calculation!M115:S115) -> 25527 | D10: =SUM(Calculation!M109:S109) -> 4003833.2 | E10: =SUM(Calculation!M110:S110) -> 904807.42 | F10: =SUM(Calculation!M111:S111) -> 78836.1 | G10: =SUM(D10:F10) -> 4987476.7 | H10: =$G$6-G10 -> 2543247.3 | I10: =IF($G$6=0,0,H10/$G$6) -> 0.33771618 | J10: =('Synertec Benchmark'!$D$5+'Synertec Benchmark'!$D$6+'Synertec Benchmark'!$D$7+'Synertec Benchmark'!$D$8+'Synertec Benchmark'!$D$9+'Synertec Benchmark'!$D$10+'Synertec Benchmark'!$D$11) -> 3809000 | K10: =G10-J10 -> 1178476.7 | L10: =IF(G10=0,0,(J10-G10)/G10) -> -0.23628716
B11: Sc. 5 · Plan Safe as offered, without SSC | C11: =SUM(Calculation!M132:S132) -> 25527 | D11: =SUM(Calculation!M126:S126) -> 4003833.2 | E11: =SUM(Calculation!M127:S127) -> 1515665.2 | F11: =SUM(Calculation!M128:S128) -> 78836.1 | G11: =SUM(D11:F11) -> 5598334.5 | H11: =$G$6-G11 -> 1932389.6 | I11: =IF($G$6=0,0,H11/$G$6) -> 0.25660077 | J11: =('Synertec Benchmark'!$D$5+'Synertec Benchmark'!$D$6+'Synertec Benchmark'!$D$7+'Synertec Benchmark'!$D$8+'Synertec Benchmark'!$D$9+'Synertec Benchmark'!$D$10+'Synertec Benchmark'!$D$11) -> 3809000 | K11: =G11-J11 -> 1789334.5 | L11: =IF(G11=0,0,(J11-G11)/G11) -> -0.31961907
B14: Lump sum (Stages 1–3)
B15: Scenario | C15: Hours | D15: IDOM | E15: Plan Safe | F15: INVAP | G15: Total price | H15: Reduction A$ | I15: Reduction % | J15: Synertec benchmark | K15: Deviation A$ | L15: Deviation %
B16: Original offer (reference) | C16: =SUM(Calculation!M47:O47) -> 11025 | D16: =SUM(Calculation!M41:O41) -> 1882791.1 | E16: =SUM(Calculation!M42:O42) -> 575618.56 | F16: =SUM(Calculation!M43:O43) -> 78836.1 | G16: =SUM(D16:F16) -> 2537245.7 | H16: =$G$16-G16 -> 0 | I16: =IF($G$16=0,0,H16/$G$16) -> 0 | J16: =('Synertec Benchmark'!$D$5+'Synertec Benchmark'!$D$6+'Synertec Benchmark'!$D$7) -> 1809000 | K16: =G16-J16 -> 728245.72 | L16: =IF(G16=0,0,(J16-G16)/G16) -> -0.28702215
B17: Sc. 1 · Base offer | C17: =SUM(Calculation!M64:O64) -> 11025 | D17: =SUM(Calculation!M58:O58) -> 1673946.8 | E17: =SUM(Calculation!M59:O59) -> 575618.56 | F17: =SUM(Calculation!M60:O60) -> 78836.1 | G17: =SUM(D17:F17) -> 2328401.4 | H17: =$G$16-G17 -> 208844.29 | I17: =IF($G$16=0,0,H17/$G$16) -> 0.082311415 | J17: =('Synertec Benchmark'!$D$5+'Synertec Benchmark'!$D$6+'Synertec Benchmark'!$D$7) -> 1809000 | K17: =G17-J17 -> 519401.44 | L17: =IF(G17=0,0,(J17-G17)/G17) -> -0.22307212
B18: Sc. 2 · Without Plan Safe HF tasks | C18: =SUM(Calculation!M81:O81) -> 9050 | D18: =SUM(Calculation!M75:O75) -> 1673946.8 | E18: =SUM(Calculation!M76:O76) -> 118878.53 | F18: =SUM(Calculation!M77:O77) -> 78836.1 | G18: =SUM(D18:F18) -> 1871661.4 | H18: =$G$16-G18 -> 665584.31 | I18: =IF($G$16=0,0,H18/$G$16) -> 0.26232552 | J18: =('Synertec Benchmark'!$D$5+'Synertec Benchmark'!$D$6+'Synertec Benchmark'!$D$7) -> 1809000 | K18: =G18-J18 -> 62661.413 | L18: =IF(G18=0,0,(J18-G18)/G18) -> -0.033479033
B19: Sc. 3 · Without Plan Safe HF tasks and SSC | C19: =SUM(Calculation!M98:O98) -> 7400 | D19: =SUM(Calculation!M92:O92) -> 1343398 | E19: =SUM(Calculation!M93:O93) -> 110833.96 | F19: =SUM(Calculation!M94:O94) -> 78836.1 | G19: =SUM(D19:F19) -> 1533068.1 | H19: =$G$16-G19 -> 1004177.7 | I19: =IF($G$16=0,0,H19/$G$16) -> 0.3957747 | J19: =('Synertec Benchmark'!$D$5+'Synertec Benchmark'!$D$6+'Synertec Benchmark'!$D$7) -> 1809000 | K19: =G19-J19 -> -275931.94 | L19: =IF(G19=0,0,(J19-G19)/G19) -> 0.17998675
B20: Sc. 4 · Without SSC, Plan Safe HF tasks at reduced price | C20: =SUM(Calculation!M115:O115) -> 9375 | D20: =SUM(Calculation!M109:O109) -> 1343398 | E20: =SUM(Calculation!M110:O110) -> 339203.97 | F20: =SUM(Calculation!M111:O111) -> 78836.1 | G20: =SUM(D20:F20) -> 1761438.1 | H20: =$G$16-G20 -> 775807.65 | I20: =IF($G$16=0,0,H20/$G$16) -> 0.30576764 | J20: =('Synertec Benchmark'!$D$5+'Synertec Benchmark'!$D$6+'Synertec Benchmark'!$D$7) -> 1809000 | K20: =G20-J20 -> -47561.923 | L20: =IF(G20=0,0,(J20-G20)/G20) -> 0.027001757
B21: Sc. 5 · Plan Safe as offered, without SSC | C21: =SUM(Calculation!M132:O132) -> 9375 | D21: =SUM(Calculation!M126:O126) -> 1343398 | E21: =SUM(Calculation!M127:O127) -> 567573.98 | F21: =SUM(Calculation!M128:O128) -> 78836.1 | G21: =SUM(D21:F21) -> 1989808.1 | H21: =$G$16-G21 -> 547437.64 | I21: =IF($G$16=0,0,H21/$G$16) -> 0.21576059 | J21: =('Synertec Benchmark'!$D$5+'Synertec Benchmark'!$D$6+'Synertec Benchmark'!$D$7) -> 1809000 | K21: =G21-J21 -> 180808.09 | L21: =IF(G21=0,0,(J21-G21)/G21) -> -0.0908671
B24: Provisional sum (Stages 4–5)
B25: Scenario | C25: Hours | D25: IDOM | E25: Plan Safe | F25: INVAP | G25: Total price | H25: Reduction A$ | I25: Reduction % | J25: Synertec benchmark | K25: Deviation A$ | L25: Deviation %
B26: Original offer (reference) | C26: =SUM(Calculation!P47:Q47) -> 16197 | D26: =SUM(Calculation!P41:Q41) -> 2979196.1 | E26: =SUM(Calculation!P42:Q42) -> 745297.35 | F26: =SUM(Calculation!P43:Q43) -> 0 | G26: =SUM(D26:F26) -> 3724493.4 | H26: =$G$26-G26 -> 0 | I26: =IF($G$26=0,0,H26/$G$26) -> 0 | J26: =('Synertec Benchmark'!$D$8+'Synertec Benchmark'!$D$9) -> 1825000 | K26: =G26-J26 -> 1899493.4 | L26: =IF(G26=0,0,(J26-G26)/G26) -> -0.51000048
B27: Sc. 1 · Base offer | C27: =SUM(Calculation!P64:Q64) -> 16197 | D27: =SUM(Calculation!P58:Q58) -> 2860028.2 | E27: =SUM(Calculation!P59:Q59) -> 745297.35 | F27: =SUM(Calculation!P60:Q60) -> 0 | G27: =SUM(D27:F27) -> 3605325.6 | H27: =$G$26-G27 -> 119167.84 | I27: =IF($G$26=0,0,H27/$G$26) -> 0.031995718 | J27: =('Synertec Benchmark'!$D$8+'Synertec Benchmark'!$D$9) -> 1825000 | K27: =G27-J27 -> 1780325.6 | L27: =IF(G27=0,0,(J27-G27)/G27) -> -0.49380439
B28: Sc. 2 · Without Plan Safe HF tasks | C28: =SUM(Calculation!P81:Q81) -> 13750 | D28: =SUM(Calculation!P75:Q75) -> 2860028.2 | E28: =SUM(Calculation!P76:Q76) -> 183659.6 | F28: =SUM(Calculation!P77:Q77) -> 0 | G28: =SUM(D28:F28) -> 3043687.8 | H28: =$G$26-G28 -> 680805.6 | I28: =IF($G$26=0,0,H28/$G$26) -> 0.18279146 | J28: =('Synertec Benchmark'!$D$8+'Synertec Benchmark'!$D$9) -> 1825000 | K28: =G28-J28 -> 1218687.8 | L28: =IF(G28=0,0,(J28-G28)/G28) -> -0.40039843
B29: Sc. 3 · Without Plan Safe HF tasks and SSC | C29: =SUM(Calculation!P98:Q98) -> 9950 | D29: =SUM(Calculation!P92:Q92) -> 2068508.4 | E29: =SUM(Calculation!P93:Q93) -> 135725.47 | F29: =SUM(Calculation!P94:Q94) -> 0 | G29: =SUM(D29:F29) -> 2204233.9 | H29: =$G$26-G29 -> 1520259.6 | I29: =IF($G$26=0,0,H29/$G$26) -> 0.40817889 | J29: =('Synertec Benchmark'!$D$8+'Synertec Benchmark'!$D$9) -> 1825000 | K29: =G29-J29 -> 379233.85 | L29: =IF(G29=0,0,(J29-G29)/G29) -> -0.17204792
B30: Sc. 4 · Without SSC, Plan Safe HF tasks at reduced price | C30: =SUM(Calculation!P115:Q115) -> 12397 | D30: =SUM(Calculation!P109:Q109) -> 2068508.4 | E30: =SUM(Calculation!P110:Q110) -> 416544.34 | F30: =SUM(Calculation!P111:Q111) -> 0 | G30: =SUM(D30:F30) -> 2485052.7 | H30: =$G$26-G30 -> 1239440.7 | I30: =IF($G$26=0,0,H30/$G$26) -> 0.33278101 | J30: =('Synertec Benchmark'!$D$8+'Synertec Benchmark'!$D$9) -> 1825000 | K30: =G30-J30 -> 660052.73 | L30: =IF(G30=0,0,(J30-G30)/G30) -> -0.26560914
B31: Sc. 5 · Plan Safe as offered, without SSC | C31: =SUM(Calculation!P132:Q132) -> 12397 | D31: =SUM(Calculation!P126:Q126) -> 2068508.4 | E31: =SUM(Calculation!P127:Q127) -> 697363.22 | F31: =SUM(Calculation!P128:Q128) -> 0 | G31: =SUM(D31:F31) -> 2765871.6 | H31: =$G$26-G31 -> 958621.82 | I31: =IF($G$26=0,0,H31/$G$26) -> 0.25738314 | J31: =('Synertec Benchmark'!$D$8+'Synertec Benchmark'!$D$9) -> 1825000 | K31: =G31-J31 -> 940871.61 | L31: =IF(G31=0,0,(J31-G31)/G31) -> -0.34017183
B34: Provisional sum (Stages 6–7)
B35: Scenario | C35: Hours | D35: IDOM | E35: Plan Safe | F35: INVAP | G35: Total price | H35: Reduction A$ | I35: Reduction % | J35: Synertec benchmark | K35: Deviation A$ | L35: Deviation %
B36: Original offer (reference) | C36: =SUM(Calculation!R47:S47) -> 5500 | D36: =SUM(Calculation!R41:S41) -> 996230.76 | E36: =SUM(Calculation!R42:S42) -> 272754.09 | F36: =SUM(Calculation!R43:S43) -> 0 | G36: =SUM(D36:F36) -> 1268984.9 | H36: =$G$36-G36 -> 0 | I36: =IF($G$36=0,0,H36/$G$36) -> 0 | J36: =('Synertec Benchmark'!$D$10+'Synertec Benchmark'!$D$11) -> 175000 | K36: =G36-J36 -> 1093984.9 | L36: =IF(G36=0,0,(J36-G36)/G36) -> -0.86209449
B37: Sc. 1 · Base offer | C37: =SUM(Calculation!R64:S64) -> 5500 | D37: =SUM(Calculation!R58:S58) -> 956381.53 | E37: =SUM(Calculation!R59:S59) -> 272754.09 | F37: =SUM(Calculation!R60:S60) -> 0 | G37: =SUM(D37:F37) -> 1229135.6 | H37: =$G$36-G37 -> 39849.23 | I37: =IF($G$36=0,0,H37/$G$36) -> 0.031402448 | J37: =('Synertec Benchmark'!$D$10+'Synertec Benchmark'!$D$11) -> 175000 | K37: =G37-J37 -> 1054135.6 | L37: =IF(G37=0,0,(J37-G37)/G37) -> -0.85762352
B38: Sc. 2 · Without Plan Safe HF tasks | C38: =SUM(Calculation!R81:S81) -> 4615 | D38: =SUM(Calculation!R75:S75) -> 956381.53 | E38: =SUM(Calculation!R76:S76) -> 69416.34 | F38: =SUM(Calculation!R77:S77) -> 0 | G38: =SUM(D38:F38) -> 1025797.9 | H38: =$G$36-G38 -> 243186.98 | I38: =IF($G$36=0,0,H38/$G$36) -> 0.19163899 | J38: =('Synertec Benchmark'!$D$10+'Synertec Benchmark'!$D$11) -> 175000 | K38: =G38-J38 -> 850797.87 | L38: =IF(G38=0,0,(J38-G38)/G38) -> -0.82940109
B39: Sc. 3 · Without Plan Safe HF tasks and SSC | C39: =SUM(Calculation!R98:S98) -> 2870 | D39: =SUM(Calculation!R92:S92) -> 591926.78 | E39: =SUM(Calculation!R93:S93) -> 47390.228 | F39: =SUM(Calculation!R94:S94) -> 0 | G39: =SUM(D39:F39) -> 639317.01 | H39: =$G$36-G39 -> 629667.84 | I39: =IF($G$36=0,0,H39/$G$36) -> 0.49619808 | J39: =('Synertec Benchmark'!$D$10+'Synertec Benchmark'!$D$11) -> 175000 | K39: =G39-J39 -> 464317.01 | L39: =IF(G39=0,0,(J39-G39)/G39) -> -0.72627038
B40: Sc. 4 · Without SSC, Plan Safe HF tasks at reduced price | C40: =SUM(Calculation!R115:S115) -> 3755 | D40: =SUM(Calculation!R109:S109) -> 591926.78 | E40: =SUM(Calculation!R110:S110) -> 149059.1 | F40: =SUM(Calculation!R111:S111) -> 0 | G40: =SUM(D40:F40) -> 740985.88 | H40: =$G$36-G40 -> 527998.97 | I40: =IF($G$36=0,0,H40/$G$36) -> 0.4160798 | J40: =('Synertec Benchmark'!$D$10+'Synertec Benchmark'!$D$11) -> 175000 | K40: =G40-J40 -> 565985.88 | L40: =IF(G40=0,0,(J40-G40)/G40) -> -0.76382816
B41: Sc. 5 · Plan Safe as offered, without SSC | C41: =SUM(Calculation!R132:S132) -> 3755 | D41: =SUM(Calculation!R126:S126) -> 591926.78 | E41: =SUM(Calculation!R127:S127) -> 250727.98 | F41: =SUM(Calculation!R128:S128) -> 0 | G41: =SUM(D41:F41) -> 842654.76 | H41: =$G$36-G41 -> 426330.09 | I41: =IF($G$36=0,0,H41/$G$36) -> 0.33596153 | J41: =('Synertec Benchmark'!$D$10+'Synertec Benchmark'!$D$11) -> 175000 | K41: =G41-J41 -> 667654.76 | L41: =IF(G41=0,0,(J41-G41)/G41) -> -0.79232301
B44: Stages 1–5 (design to IFC)
B45: Scenario | C45: Hours | D45: IDOM | E45: Plan Safe | F45: INVAP | G45: Total price | H45: Reduction A$ | I45: Reduction % | J45: Synertec benchmark | K45: Deviation A$ | L45: Deviation %
B46: Original offer (reference) | C46: =SUM(Calculation!M47:Q47) -> 27222 | D46: =SUM(Calculation!M41:Q41) -> 4861987.1 | E46: =SUM(Calculation!M42:Q42) -> 1320915.9 | F46: =SUM(Calculation!M43:Q43) -> 78836.1 | G46: =SUM(D46:F46) -> 6261739.2 | H46: =$G$46-G46 -> 0 | I46: =IF($G$46=0,0,H46/$G$46) -> 0 | J46: =('Synertec Benchmark'!$D$5+'Synertec Benchmark'!$D$6+'Synertec Benchmark'!$D$7+'Synertec Benchmark'!$D$8+'Synertec Benchmark'!$D$9) -> 3634000 | K46: =G46-J46 -> 2627739.2 | L46: =IF(G46=0,0,(J46-G46)/G46) -> -0.41965005
B47: Sc. 1 · Base offer | C47: =SUM(Calculation!M64:Q64) -> 27222 | D47: =SUM(Calculation!M58:Q58) -> 4533975 | E47: =SUM(Calculation!M59:Q59) -> 1320915.9 | F47: =SUM(Calculation!M60:Q60) -> 78836.1 | G47: =SUM(D47:F47) -> 5933727 | H47: =$G$46-G47 -> 328012.13 | I47: =IF($G$46=0,0,H47/$G$46) -> 0.052383551 | J47: =('Synertec Benchmark'!$D$5+'Synertec Benchmark'!$D$6+'Synertec Benchmark'!$D$7+'Synertec Benchmark'!$D$8+'Synertec Benchmark'!$D$9) -> 3634000 | K47: =G47-J47 -> 2299727 | L47: =IF(G47=0,0,(J47-G47)/G47) -> -0.38756873
B48: Sc. 2 · Without Plan Safe HF tasks | C48: =SUM(Calculation!M81:Q81) -> 22800 | D48: =SUM(Calculation!M75:Q75) -> 4533975 | E48: =SUM(Calculation!M76:Q76) -> 302538.13 | F48: =SUM(Calculation!M77:Q77) -> 78836.1 | G48: =SUM(D48:F48) -> 4915349.2 | H48: =$G$46-G48 -> 1346389.9 | I48: =IF($G$46=0,0,H48/$G$46) -> 0.21501852 | J48: =('Synertec Benchmark'!$D$5+'Synertec Benchmark'!$D$6+'Synertec Benchmark'!$D$7+'Synertec Benchmark'!$D$8+'Synertec Benchmark'!$D$9) -> 3634000 | K48: =G48-J48 -> 1281349.2 | L48: =IF(G48=0,0,(J48-G48)/G48) -> -0.26068326
B49: Sc. 3 · Without Plan Safe HF tasks and SSC | C49: =SUM(Calculation!M98:Q98) -> 17350 | D49: =SUM(Calculation!M92:Q92) -> 3411906.4 | E49: =SUM(Calculation!M93:Q93) -> 246559.42 | F49: =SUM(Calculation!M94:Q94) -> 78836.1 | G49: =SUM(D49:F49) -> 3737301.9 | H49: =$G$46-G49 -> 2524437.2 | I49: =IF($G$46=0,0,H49/$G$46) -> 0.40315273 | J49: =('Synertec Benchmark'!$D$5+'Synertec Benchmark'!$D$6+'Synertec Benchmark'!$D$7+'Synertec Benchmark'!$D$8+'Synertec Benchmark'!$D$9) -> 3634000 | K49: =G49-J49 -> 103301.92 | L49: =IF(G49=0,0,(J49-G49)/G49) -> -0.027640773
...

Sheet Synertec Benchmark
B1: Synertec benchmark comparison
B2: Synertec proposal for the nuclear and radiological scope, by stage (A$). Fixed for every scenario. Deviation A$ = price − benchmark; deviation % = (benchmark − price) / price.
B4: Stage | C4: Description | D4: Synertec proposal (A$) | E4: Original offer (A$) | F4: Deviation A$ | G4: Deviation %
B5: S1 | C5: Project Familiarisation & Initiation | D5: 106000 | E5: =Calculation!M44 -> 335082.83 | F5: =E5-D5 -> 229082.83 | G5: =IF(E5=0,0,(D5-E5)/E5) -> -0.6836603
B6: S2 | C6: Concept Design | D6: 453000 | E6: =Calculation!N44 -> 732839.1 | F6: =E6-D6 -> 279839.1 | G6: =IF(E6=0,0,(D6-E6)/E6) -> -0.38185613
B7: S3 | C7: Preliminary Design | D7: 1250000 | E7: =Calculation!O44 -> 1469323.8 | F7: =E7-D7 -> 219323.8 | G7: =IF(E7=0,0,(D7-E7)/E7) -> -0.14926853
B8: S4 | C8: Detailed Design | D8: 1455000 | E8: =Calculation!P44 -> 3183882.6 | F8: =E8-D8 -> 1728882.6 | G8: =IF(E8=0,0,(D8-E8)/E8) -> -0.54301078
B9: S5 | C9: Issued For Construction | D9: 370000 | E9: =Calculation!Q44 -> 540610.88 | F9: =E9-D9 -> 170610.88 | G9: =IF(E9=0,0,(D9-E9)/E9) -> -0.31558905
B10: S6 | C10: Construction Support | D10: 102000 | E10: =Calculation!R44 -> 775079.55 | F10: =E10-D10 -> 673079.55 | G10: =IF(E10=0,0,(D10-E10)/E10) -> -0.8684006
B11: S7 | C11: Commissioning, Qualification & Validation | D11: 73000 | E11: =Calculation!S44 -> 493905.3 | F11: =E11-D11 -> 420905.3 | G11: =IF(E11=0,0,(D11-E11)/E11) -> -0.85219839
B12: TOTAL | D12: =SUM(D5:D11) -> 3809000 | E12: =SUM(E5:E11) -> 7530724 | F12: =SUM(F5:F11) -> 3721724 | G12: =IF(E12=0,0,(D12-E12)/E12) -> -0.49420534
B15: Scenario prices against the benchmark, by stage (with the commercial assumptions applied)
D16: Sc. 1 · Base offer | F16: Sc. 2 · Without Plan Safe HF tasks | H16: Sc. 3 · Without Plan Safe HF tasks and SSC | J16: Sc. 4 · Without SSC, Plan Safe HF tasks at reduced price | L16: Sc. 5 · Plan Safe as offered, without SSC
B17: Stage | C17: Synertec | D17: Price (A$) | E17: Deviation % | F17: Price (A$) | G17: Deviation % | H17: Price (A$) | I17: Deviation % | J17: Price (A$) | K17: Deviation % | L17: Price (A$) | M17: Deviation %
B18: S1 | C18: ='Synertec Benchmark'!$D$5 -> 106000 | D18: =Calculation!M61 -> 329748.36 | E18: =IF(D18=0,0,($C18-D18)/D18) -> -0.67854275 | F18: =Calculation!M78 -> 221681.31 | G18: =IF(F18=0,0,($C18-F18)/F18) -> -0.52183609 | H18: =Calculation!M95 -> 221681.31 | I18: =IF(H18=0,0,($C18-H18)/H18) -> -0.52183609 | J18: =Calculation!M112 -> 275714.83 | K18: =IF(J18=0,0,($C18-J18)/J18) -> -0.6155448 | L18: =Calculation!M129 -> 329748.36 | M18: =IF(L18=0,0,($C18-L18)/L18) -> -0.67854275
B19: S2 | C19: ='Synertec Benchmark'!$D$6 -> 453000 | D19: =Calculation!N61 -> 577845.85 | E19: =IF(D19=0,0,($C19-D19)/D19) -> -0.2160539 | F19: =Calculation!N78 -> 418979.28 | G19: =IF(F19=0,0,($C19-F19)/F19) -> 0.081199058 | H19: =Calculation!N95 -> 348056.02 | I19: =IF(H19=0,0,($C19-H19)/H19) -> 0.30151461 | J19: =Calculation!N112 -> 427489.31 | K19: =IF(J19=0,0,($C19-J19)/J19) -> 0.059675617 | L19: =Calculation!N129 -> 506922.6 | M19: =IF(L19=0,0,($C19-L19)/L19) -> -0.10637245
B20: S3 | C20: ='Synertec Benchmark'!$D$7 -> 1250000 | D20: =Calculation!O61 -> 1420807.2 | E20: =IF(D20=0,0,($C20-D20)/D20) -> -0.12021844 | F20: =Calculation!O78 -> 1231000.8 | G20: =IF(F20=0,0,($C20-F20)/F20) -> 0.015433922 | H20: =Calculation!O95 -> 963330.73 | I20: =IF(H20=0,0,($C20-H20)/H20) -> 0.29758136 | J20: =Calculation!O112 -> 1058233.9 | K20: =IF(J20=0,0,($C20-J20)/J20) -> 0.1812133 | L20: =Calculation!O129 -> 1153137.1 | M20: =IF(L20=0,0,($C20-L20)/L20) -> 0.083999433
B21: S4 | C21: ='Synertec Benchmark'!$D$8 -> 1455000 | D21: =Calculation!P61 -> 3079920.1 | E21: =IF(D21=0,0,($C21-D21)/D21) -> -0.52758515 | F21: =Calculation!P78 -> 2646815.5 | G21: =IF(F21=0,0,($C21-F21)/F21) -> -0.4502828 | H21: =Calculation!P95 -> 2045662.6 | I21: =IF(H21=0,0,($C21-H21)/H21) -> -0.28873901 | J21: =Calculation!P112 -> 2262214.9 | K21: =IF(J21=0,0,($C21-J21)/J21) -> -0.35682503 | L21: =Calculation!P129 -> 2478767.2 | M21: =IF(L21=0,0,($C21-L21)/L21) -> -0.41301467
B22: S5 | C22: ='Synertec Benchmark'!$D$9 -> 370000 | D22: =Calculation!Q61 -> 525405.49 | E22: =IF(D22=0,0,($C22-D22)/D22) -> -0.29578201 | F22: =Calculation!Q78 -> 396872.36 | G22: =IF(F22=0,0,($C22-F22)/F22) -> -0.067710343 | H22: =Calculation!Q95 -> 158571.25 | I22: =IF(H22=0,0,($C22-H22)/H22) -> 1.3333359 | J22: =Calculation!Q112 -> 222837.81 | K22: =IF(J22=0,0,($C22-J22)/J22) -> 0.66040042 | L22: =Calculation!Q129 -> 287104.38 | M22: =IF(L22=0,0,($C22-L22)/L22) -> 0.28872992
B23: S6 | C23: ='Synertec Benchmark'!$D$10 -> 102000 | D23: =Calculation!R61 -> 751719.06 | E23: =IF(D23=0,0,($C23-D23)/D23) -> -0.86431101 | F23: =Calculation!R78 -> 604829.31 | G23: =IF(F23=0,0,($C23-F23)/F23) -> -0.83135738 | H23: =Calculation!R95 -> 349428.25 | I23: =IF(H23=0,0,($C23-H23)/H23) -> -0.70809458 | J23: =Calculation!R112 -> 422873.12 | K23: =IF(J23=0,0,($C23-J23)/J23) -> -0.7587929 | L23: =Calculation!R129 -> 496318 | M23: =IF(L23=0,0,($C23-L23)/L23) -> -0.7944866
B24: S7 | C24: ='Synertec Benchmark'!$D$11 -> 73000 | D24: =Calculation!S61 -> 477416.56 | E24: =IF(D24=0,0,($C24-D24)/D24) -> -0.8470937 | F24: =Calculation!S78 -> 420968.56 | G24: =IF(F24=0,0,($C24-F24)/F24) -> -0.82659038 | H24: =Calculation!S95 -> 289888.76 | I24: =IF(H24=0,0,($C24-H24)/H24) -> -0.74817927 | J24: =Calculation!S112 -> 318112.76 | K24: =IF(J24=0,0,($C24-J24)/J24) -> -0.77052162 | L24: =Calculation!S129 -> 346336.76 | M24: =IF(L24=0,0,($C24-L24)/L24) -> -0.78922249
B25: S1–S3 | C25: =('Synertec Benchmark'!$D$5+'Synertec Benchmark'!$D$6+'Synertec Benchmark'!$D$7) -> 1809000 | D25: =SUM(Calculation!M61:O61) -> 2328401.4 | E25: =IF(D25=0,0,($C25-D25)/D25) -> -0.22307212 | F25: =SUM(Calculation!M78:O78) -> 1871661.4 | G25: =IF(F25=0,0,($C25-F25)/F25) -> -0.033479033 | H25: =SUM(Calculation!M95:O95) -> 1533068.1 | I25: =IF(H25=0,0,($C25-H25)/H25) -> 0.17998675 | J25: =SUM(Calculation!M112:O112) -> 1761438.1 | K25: =IF(J25=0,0,($C25-J25)/J25) -> 0.027001757 | L25: =SUM(Calculation!M129:O129) -> 1989808.1 | M25: =IF(L25=0,0,($C25-L25)/L25) -> -0.0908671
B26: S4–S5 | C26: =('Synertec Benchmark'!$D$8+'Synertec Benchmark'!$D$9) -> 1825000 | D26: =SUM(Calculation!P61:Q61) -> 3605325.6 | E26: =IF(D26=0,0,($C26-D26)/D26) -> -0.49380439 | F26: =SUM(Calculation!P78:Q78) -> 3043687.8 | G26: =IF(F26=0,0,($C26-F26)/F26) -> -0.40039843 | H26: =SUM(Calculation!P95:Q95) -> 2204233.9 | I26: =IF(H26=0,0,($C26-H26)/H26) -> -0.17204792 | J26: =SUM(Calculation!P112:Q112) -> 2485052.7 | K26: =IF(J26=0,0,($C26-J26)/J26) -> -0.26560914 | L26: =SUM(Calculation!P129:Q129) -> 2765871.6 | M26: =IF(L26=0,0,($C26-L26)/L26) -> -0.34017183
B27: S6–S7 | C27: =('Synertec Benchmark'!$D$10+'Synertec Benchmark'!$D$11) -> 175000 | D27: =SUM(Calculation!R61:S61) -> 1229135.6 | E27: =IF(D27=0,0,($C27-D27)/D27) -> -0.85762352 | F27: =SUM(Calculation!R78:S78) -> 1025797.9 | G27: =IF(F27=0,0,($C27-F27)/F27) -> -0.82940109 | H27: =SUM(Calculation!R95:S95) -> 639317.01 | I27: =IF(H27=0,0,($C27-H27)/H27) -> -0.72627038 | J27: =SUM(Calculation!R112:S112) -> 740985.88 | K27: =IF(J27=0,0,($C27-J27)/J27) -> -0.76382816 | L27: =SUM(Calculation!R129:S129) -> 842654.76 | M27: =IF(L27=0,0,($C27-L27)/L27) -> -0.79232301
B28: S1–S5 | C28: =('Synertec Benchmark'!$D$5+'Synertec Benchmark'!$D$6+'Synertec Benchmark'!$D$7+'Synertec Benchmark'!$D$8+'Synertec Benchmark'!$D$9) -> 3634000 | D28: =SUM(Calculation!M61:Q61) -> 5933727 | E28: =IF(D28=0,0,($C28-D28)/D28) -> -0.38756873 | F28: =SUM(Calculation!M78:Q78) -> 4915349.2 | G28: =IF(F28=0,0,($C28-F28)/F28) -> -0.26068326 | H28: =SUM(Calculation!M95:Q95) -> 3737301.9 | I28: =IF(H28=0,0,($C28-H28)/H28) -> -0.027640773 | J28: =SUM(Calculation!M112:Q112) -> 4246490.8 | K28: =IF(J28=0,0,($C28-J28)/J28) -> -0.14423458 | L28: =SUM(Calculation!M129:Q129) -> 4755679.7 | M28: =IF(L28=0,0,($C28-L28)/L28) -> -0.23586107
B29: TOTAL | C29: =('Synertec Benchmark'!$D$5+'Synertec Benchmark'!$D$6+'Synertec Benchmark'!$D$7+'Synertec Benchmark'!$D$8+'Synertec Benchmark'!$D$9+'Synertec Benchmark'!$D$10+'Synertec Benchmark'!$D$11) -> 3809000 | D29: =SUM(Calculation!M61:S61) -> 7162862.6 | E29: =IF(D29=0,0,($C29-D29)/D29) -> -0.46822937 | F29: =SUM(Calculation!M78:S78) -> 5941147.1 | G29: =IF(F29=0,0,($C29-F29)/F29) -> -0.35887802 | H29: =SUM(Calculation!M95:S95) -> 4376618.9 | I29: =IF(H29=0,0,($C29-H29)/H29) -> -0.12969348 | J29: =SUM(Calculation!M112:S112) -> 4987476.7 | K29: =IF(J29=0,0,($C29-J29)/J29) -> -0.23628716 | L29: =SUM(Calculation!M129:S129) -> 5598334.5 | M29: =IF(L29=0,0,($C29-L29)/L29) -> -0.31961907
B31: Negative deviation = the Synertec benchmark is below the scenario price. Blocks: S1–S3 lump sum, S4–S5 and S6–S7 provisional sums, S1–S5 design to IFC.

Sheet Assumptions
B1: Assumptions and inputs
B2: Yellow cells with blue text are inputs; grey cells are fixed values from the original offer. Every sheet recalculates from these cells.
B4: Commercial assumptions applied to every scenario
B5: Stage 2 rework allowance included in the original offer | C5: 0.35 | D5: Carried in the original offer as a 35% surcharge on IDOM's Stage 2 tasks.
B6: Stage 2 rework allowance considered in this proposal | C6: 0 | D6: 0% = the allowance is released in full: all deliverables are assumed right first time.
B7: Commercial discount on IDOM's scope | C7: 0.04 | D7: Applied to everything IDOM invoices, after the rework release. Not applied to Plan Safe or INVAP.
B8: Optional levers
B9: Include INVAP (Conceptual Design Verification)? | C9: Yes | D9: No = INVAP's Stage 1 verification is removed from every scenario.
B10: Price deliverable S1 as a two-week single issue? | C10: No | D10: Yes = Safety Assurance Plan / Safety Integration Plan issued once at framework level in Stage 1, with no Stage 2 update.
B11: Deliverable S1 two-week option: hours | C11: 165 | D11: Ten working days, approximately 2.2 senior authors.
B12: Deliverable S1 two-week option: price (A$) | C12: 38675 | D12: A$41,769 inclusive of variable costs (information only).
B13: Subcontractor parameters
B14: Plan Safe share of the shared deliverables | C14: 0.1 | D14: Share of the deliverables led by IDOM with specialist input. Moves money between IDOM and Plan Safe; does not change the total.
B15: Plan Safe HF tasks price factor in scenario 4 | C15: 0.5 | D15: 50% = Plan Safe's own HF deliverables at half price.
B17: Scenario definitions
B18: Scenario | C18: Name | D18: Definition
B19: Scenario 1 | C19: Base offer | D19: Full scope as offered.
B20: Scenario 2 | C20: Without Plan Safe HF tasks | D20: Removes Plan Safe's four human factors deliverables: S2, S3, S8 and S30.
B21: Scenario 3 | C21: Without Plan Safe HF tasks and SSC | D21: Removes the four HF deliverables and the SSC group: S26, S27, S28 and S29.
B22: Scenario 4 | C22: Without SSC, Plan Safe HF tasks at reduced price | D22: Removes the SSC group; Plan Safe's HF deliverables at the price factor above.
B23: Scenario 5 | C23: Plan Safe as offered, without SSC | D23: Removes the SSC group only; Plan Safe scope as offered.
B25: Every scenario includes the commercial assumptions above. The original offer (reference) is the offer as submitted, with no adjustments.

Sheet Calculation
A1: Calculation engine — do not edit (driven by Assumptions and Data)
M3: S1 | N3: S2 | O3: S3 | P3: S4 | Q3: S5 | R3: S6 | S3: S7 | T3: S1 | U3: S2 | V3: S3 | W3: S4 | X3: S5 | Y3: S6 | Z3: S7
A4: Code | B4: Deliverable | C4: Type | D4: Group | E4: % IDOM | F4: % Plan Safe | G4: % INVAP | H4: Factor Sc.1 | I4: Factor Sc.2 | J4: Factor Sc.3 | K4: Factor Sc.4 | L4: Factor Sc.5 | M4: A$ S1 | N4: A$ S2 | O4: A$ S3 | P4: A$ S4 | Q4: A$ S5 | R4: A$ S6 | S4: A$ S7 | T4: h S1 | U4: h S2 | V4: h S3 | W4: h S4 | X4: h S5 | Y4: h S6 | Z4: h S7 | AA4: A$ S1–S3 | AB4: A$ S4–S5 | AC4: A$ S6–S7 | AD4: A$ S1–S5 | AE4: A$ Total
A5: E94 | B5: Radiological Zoning Layout drawing(s) | C5: IDOM | D5: Other | E5: =IF(C5="IDOM",1,IF(C5="Shared",1-Assumptions!$C$14,0)) -> 1 | F5: =IF(C5="Plan Safe",1,IF(C5="Shared",Assumptions!$C$14,0)) -> 0 | G5: =IF(C5="INVAP",1,0) -> 0 | H5: 1 | I5: 1 | J5: 1 | K5: 1 | L5: 1 | M5: =SUMIFS(Data!$J$5:$J$291,Data!$E$5:$E$291,$A5,Data!$F$5:$F$291,"S1") -> 0 | N5: =SUMIFS(Data!$J$5:$J$291,Data!$E$5:$E$291,$A5,Data!$F$5:$F$291,"S2") -> 35206.5 | O5: =SUMIFS(Data!$J$5:$J$291,Data!$E$5:$E$291,$A5,Data!$F$5:$F$291,"S3") -> 58869.825 | P5: =SUMIFS(Data!$J$5:$J$291,Data!$E$5:$E$291,$A5,Data!$F$5:$F$291,"S4") -> 85451.1 | Q5: =SUMIFS(Data!$J$5:$J$291,Data!$E$5:$E$291,$A5,Data!$F$5:$F$291,"S5") -> 0 | R5: =SUMIFS(Data!$J$5:$J$291,Data!$E$5:$E$291,$A5,Data!$F$5:$F$291,"S6") -> 0 | S5: =SUMIFS(Data!$J$5:$J$291,Data!$E$5:$E$291,$A5,Data!$F$5:$F$291,"S7") -> 0 | T5: =SUMIFS(Data!$H$5:$H$291,Data!$E$5:$E$291,$A5,Data!$F$5:$F$291,"S1") -> 0 | U5: =SUMIFS(Data!$H$5:$H$291,Data!$E$5:$E$291,$A5,Data!$F$5:$F$291,"S2") -> 185 | V5: =SUMIFS(Data!$H$5:$H$291,Data!$E$5:$E$291,$A5,Data!$F$5:$F$291,"S3") -> 315 | W5: =SUMIFS(Data!$H$5:$H$291,Data!$E$5:$E$291,$A5,Data!$F$5:$F$291,"S4") -> 430 | X5: =SUMIFS(Data!$H$5:$H$291,Data!$E$5:$E$291,$A5,Data!$F$5:$F$291,"S5") -> 0 | Y5: =SUMIFS(Data!$H$5:$H$291,Data!$E$5:$E$291,$A5,Data!$F$5:$F$291,"S6") -> 0 | Z5: =SUMIFS(Data!$H$5:$H$291,Data!$E$5:$E$291,$A5,Data!$F$5:$F$291,"S7") -> 0 | AA5: =M5+N5+O5 -> 94076.325 | AB5: =P5+Q5 -> 85451.1 | AC5: =R5+S5 -> 0 | AD5: =M5+N5+O5+P5+Q5 -> 179527.42 | AE5: =M5+N5+O5+P5+Q5+R5+S5 -> 179527.42
A6: S1 | B6: Safety Assurance Plan / Safety Integration Plan | C6: Shared | D6: Other | E6: =IF(C6="IDOM",1,IF(C6="Shared",1-Assumptions!$C$14,0)) -> 0.9 | F6: =IF(C6="Plan Safe",1,IF(C6="Shared",Assumptions!$C$14,0)) -> 0.1 | G6: =IF(C6="INVAP",1,0) -> 0 | H6: 1 | I6: 1 | J6: 1 | K6: 1 | L6: 1 | M6: =SUMIFS(Data!$J$5:$J$291,Data!$E$5:$E$291,$A6,Data!$F$5:$F$291,"S1") -> 148179.67 | N6: =SUMIFS(Data!$J$5:$J$291,Data!$E$5:$E$291,$A6,Data!$F$5:$F$291,"S2") -> 284239.2 | O6: =SUMIFS(Data!$J$5:$J$291,Data!$E$5:$E$291,$A6,Data!$F$5:$F$291,"S3") -> 0 | P6: =SUMIFS(Data!$J$5:$J$291,Data!$E$5:$E$291,$A6,Data!$F$5:$F$291,"S4") -> 0 | Q6: =SUMIFS(Data!$J$5:$J$291,Data!$E$5:$E$291,$A6,Data!$F$5:$F$291,"S5") -> 0 | R6: =SUMIFS(Data!$J$5:$J$291,Data!$E$5:$E$291,$A6,Data!$F$5:$F$291,"S6") -> 0 | S6: =SUMIFS(Data!$J$5:$J$291,Data!$E$5:$E$291,$A6,Data!$F$5:$F$291,"S7") -> 0 | T6: =SUMIFS(Data!$H$5:$H$291,Data!$E$5:$E$291,$A6,Data!$F$5:$F$291,"S1") -> 625 | U6: =SUMIFS(Data!$H$5:$H$291,Data!$E$5:$E$291,$A6,Data!$F$5:$F$291,"S2") -> 1200 | V6: =SUMIFS(Data!$H$5:$H$291,Data!$E$5:$E$291,$A6,Data!$F$5:$F$291,"S3") -> 0 | W6: =SUMIFS(Data!$H$5:$H$291,Data!$E$5:$E$291,$A6,Data!$F$5:$F$291,"S4") -> 0 | X6: =SUMIFS(Data!$H$5:$H$291,Data!$E$5:$E$291,$A6,Data!$F$5:$F$291,"S5") -> 0 | Y6: =SUMIFS(Data!$H$5:$H$291,Data!$E$5:$E$291,$A6,Data!$F$5:$F$291,"S6") -> 0 | Z6: =SUMIFS(Data!$H$5:$H$291,Data!$E$5:$E$291,$A6,Data!$F$5:$F$291,"S7") -> 0 | AA6: =M6+N6+O6 -> 432418.88 | AB6: =P6+Q6 -> 0 | AC6: =R6+S6 -> 0 | AD6: =M6+N6+O6+P6+Q6 -> 432418.88 | AE6: =M6+N6+O6+P6+Q6+R6+S6 -> 432418.88
A7: S9 | B7: Deterministic Safety Assessment(s) (DSA) / Inherent Risk Assessment(s) | C7: Shared | D7: Other | E7: =IF(C7="IDOM",1,IF(C7="Shared",1-Assumptions!$C$14,0)) -> 0.9 | F7: =IF(C7="Plan Safe",1,IF(C7="Shared",Assumptions!$C$14,0)) -> 0.1 | G7: =IF(C7="INVAP",1,0) -> 0 | H7: 1 | I7: 1 | J7: 1 | K7: 1 | L7: 1 | M7: =SUMIFS(Data!$J$5:$J$291,Data!$E$5:$E$291,$A7,Data!$F$5:$F$291,"S1") -> 0 | N7: =SUMIFS(Data!$J$5:$J$291,Data!$E$5:$E$291,$A7,Data!$F$5:$F$291,"S2") -> 0 | O7: =SUMIFS(Data!$J$5:$J$291,Data!$E$5:$E$291,$A7,Data!$F$5:$F$291,"S3") -> 323392.65 | P7: =SUMIFS(Data!$J$5:$J$291,Data!$E$5:$E$291,$A7,Data!$F$5:$F$291,"S4") -> 237629.17 | Q7: =SUMIFS(Data!$J$5:$J$291,Data!$E$5:$E$291,$A7,Data!$F$5:$F$291,"S5") -> 0 | R7: =SUMIFS(Data!$J$5:$J$291,Data!$E$5:$E$291,$A7,Data!$F$5:$F$291,"S6") -> 92514.45 | S7: =SUMIFS(Data!$J$5:$J$291,Data!$E$5:$E$291,$A7,Data!$F$5:$F$291,"S7") -> 57256.5 | T7: =SUMIFS(Data!$H$5:$H$291,Data!$E$5:$E$291,$A7,Data!$F$5:$F$291,"S1") -> 0 | U7: =SUMIFS(Data!$H$5:$H$291,Data!$E$5:$E$291,$A7,Data!$F$5:$F$291,"S2") -> 0 | V7: =SUMIFS(Data!$H$5:$H$291,Data!$E$5:$E$291,$A7,Data!$F$5:$F$291,"S3") -> 1385 | W7: =SUMIFS(Data!$H$5:$H$291,Data!$E$5:$E$291,$A7,Data!$F$5:$F$291,"S4") -> 1015 | X7: =SUMIFS(Data!$H$5:$H$291,Data!$E$5:$E$291,$A7,Data!$F$5:$F$291,"S5") -> 0 | Y7: =SUMIFS(Data!$H$5:$H$291,Data!$E$5:$E$291,$A7,Data!$F$5:$F$291,"S6") -> 390 | Z7: =SUMIFS(Data!$H$5:$H$291,Data!$E$5:$E$291,$A7,Data!$F$5:$F$291,"S7") -> 245 | AA7: =M7+N7+O7 -> 323392.65 | AB7: =P7+Q7 -> 237629.17 | AC7: =R7+S7 -> 149770.95 | AD7: =M7+N7+O7+P7+Q7 -> 561021.82 | AE7: =M7+N7+O7+P7+Q7+R7+S7 -> 710792.78
A8: S10 | B8: Probablisitic Safety Assessment / Quantitative Risk Assessment (s) (QRA) | C8: Shared | D8: Other | E8: =IF(C8="IDOM",1,IF(C8="Shared",1-Assumptions!$C$14,0)) -> 0.9 | F8: =IF(C8="Plan Safe",1,IF(C8="Shared",Assumptions!$C$14,0)) -> 0.1 | G8: =IF(C8="INVAP",1,0) -> 0 | H8: 1 | I8: 1 | J8: 1 | K8: 1 | L8: 1 | M8: =SUMIFS(Data!$J$5:$J$291,Data!$E$5:$E$291,$A8,Data!$F$5:$F$291,"S1") -> 0 | N8: =SUMIFS(Data!$J$5:$J$291,Data!$E$5:$E$291,$A8,Data!$F$5:$F$291,"S2") -> 0 | O8: =SUMIFS(Data!$J$5:$J$291,Data!$E$5:$E$291,$A8,Data!$F$5:$F$291,"S3") -> 0 | P8: =SUMIFS(Data!$J$5:$J$291,Data!$E$5:$E$291,$A8,Data!$F$5:$F$291,"S4") -> 222212.55 | Q8: =SUMIFS(Data!$J$5:$J$291,Data!$E$5:$E$291,$A8,Data!$F$5:$F$291,"S5") -> 0 | R8: =SUMIFS(Data!$J$5:$J$291,Data!$E$5:$E$291,$A8,Data!$F$5:$F$291,"S6") -> 42192.675 | S8: =SUMIFS(Data!$J$5:$J$291,Data!$E$5:$E$291,$A8,Data!$F$5:$F$291,"S7") -> 26985.525 | T8: =SUMIFS(Data!$H$5:$H$291,Data!$E$5:$E$291,$A8,Data!$F$5:$F$291,"S1") -> 0 | U8: =SUMIFS(Data!$H$5:$H$291,Data!$E$5:$E$291,$A8,Data!$F$5:$F$291,"S2") -> 0 | V8: =SUMIFS(Data!$H$5:$H$291,Data!$E$5:$E$291,$A8,Data!$F$5:$F$291,"S3") -> 0 | W8: =SUMIFS(Data!$H$5:$H$291,Data!$E$5:$E$291,$A8,Data!$F$5:$F$291,"S4") -> 950 | X8: =SUMIFS(Data!$H$5:$H$291,Data!$E$5:$E$291,$A8,Data!$F$5:$F$291,"S5") -> 0 | Y8: =SUMIFS(Data!$H$5:$H$291,Data!$E$5:$E$291,$A8,Data!$F$5:$F$291,"S6") -> 180 | Z8: =SUMIFS(Data!$H$5:$H$291,Data!$E$5:$E$291,$A8,Data!$F$5:$F$291,"S7") -> 115 | AA8: =M8+N8+O8 -> 0 | AB8: =P8+Q8 -> 222212.55 | AC8: =R8+S8 -> 69178.2 | AD8: =M8+N8+O8+P8+Q8 -> 222212.55 | AE8: =M8+N8+O8+P8+Q8+R8+S8 -> 291390.75
A9: S17 | B9: ALARP (Optioneering) Study | C9: Shared | D9: Other | E9: =IF(C9="IDOM",1,IF(C9="Shared",1-Assumptions!$C$14,0)) -> 0.9 | F9: =IF(C9="Plan Safe",1,IF(C9="Shared",Assumptions!$C$14,0)) -> 0.1 | G9: =IF(C9="INVAP",1,0) -> 0 | H9: 1 | I9: 1 | J9: 1 | K9: 1 | L9: 1 | M9: =SUMIFS(Data!$J$5:$J$291,Data!$E$5:$E$291,$A9,Data!$F$5:$F$291,"S1") -> 0 | N9: =SUMIFS(Data!$J$5:$J$291,Data!$E$5:$E$291,$A9,Data!$F$5:$F$291,"S2") -> 90335.175 | O9: =SUMIFS(Data!$J$5:$J$291,Data!$E$5:$E$291,$A9,Data!$F$5:$F$291,"S3") -> 151656.23 | P9: =SUMIFS(Data!$J$5:$J$291,Data!$E$5:$E$291,$A9,Data!$F$5:$F$291,"S4") -> 211896.83 | Q9: =SUMIFS(Data!$J$5:$J$291,Data!$E$5:$E$291,$A9,Data!$F$5:$F$291,"S5") -> 0 | R9: =SUMIFS(Data!$J$5:$J$291,Data!$E$5:$E$291,$A9,Data!$F$5:$F$291,"S6") -> 0 | S9: =SUMIFS(Data!$J$5:$J$291,Data!$E$5:$E$291,$A9,Data!$F$5:$F$291,"S7") -> 0 | T9: =SUMIFS(Data!$H$5:$H$291,Data!$E$5:$E$291,$A9,Data!$F$5:$F$291,"S1") -> 0 | U9: =SUMIFS(Data!$H$5:$H$291,Data!$E$5:$E$291,$A9,Data!$F$5:$F$291,"S2") -> 385 | V9: =SUMIFS(Data!$H$5:$H$291,Data!$E$5:$E$291,$A9,Data!$F$5:$F$291,"S3") -> 650 | W9: =SUMIFS(Data!$H$5:$H$291,Data!$E$5:$E$291,$A9,Data!$F$5:$F$291,"S4") -> 905 | X9: =SUMIFS(Data!$H$5:$H$291,Data!$E$5:$E$291,$A9,Data!$F$5:$F$291,"S5") -> 0 | Y9: =SUMIFS(Data!$H$5:$H$291,Data!$E$5:$E$291,$A9,Data!$F$5:$F$291,"S6") -> 0 | Z9: =SUMIFS(Data!$H$5:$H$291,Data!$E$5:$E$291,$A9,Data!$F$5:$F$291,"S7") -> 0 | AA9: =M9+N9+O9 -> 241991.4 | AB9: =P9+Q9 -> 211896.83 | AC9: =R9+S9 -> 0 | AD9: =M9+N9+O9+P9+Q9 -> 453888.22 | AE9: =M9+N9+O9+P9+Q9+R9+S9 -> 453888.22
A10: S18 | B10: ALARP Summary Report (ALARP/SFARP Statement Report) | C10: Shared | D10: Other | E10: =IF(C10="IDOM",1,IF(C10="Shared",1-Assumptions!$C$14,0)) -> 0.9 | F10: =IF(C10="Plan Safe",1,IF(C10="Shared",Assumptions!$C$14,0)) -> 0.1 | G10: =IF(C10="INVAP",1,0) -> 0 | H10: 1 | I10: 1 | J10: 1 | K10: 1 | L10: 1 | M10: =SUMIFS(Data!$J$5:$J$291,Data!$E$5:$E$291,$A10,Data!$F$5:$F$291,"S1") -> 0 | N10: =SUMIFS(Data!$J$5:$J$291,Data!$E$5:$E$291,$A10,Data!$F$5:$F$291,"S2") -> 0 | O10: =SUMIFS(Data!$J$5:$J$291,Data!$E$5:$E$291,$A10,Data!$F$5:$F$291,"S3") -> 0 | P10: =SUMIFS(Data!$J$5:$J$291,Data!$E$5:$E$291,$A10,Data!$F$5:$F$291,"S4") -> 142939.12 | Q10: =SUMIFS(Data!$J$5:$J$291,Data!$E$5:$E$291,$A10,Data!$F$5:$F$291,"S5") -> 0 | R10: =SUMIFS(Data!$J$5:$J$291,Data!$E$5:$E$291,$A10,Data!$F$5:$F$291,"S6") -> 0 | S10: =SUMIFS(Data!$J$5:$J$291,Data!$E$5:$E$291,$A10,Data!$F$5:$F$291,"S7") -> 0 | T10: =SUMIFS(Data!$H$5:$H$291,Data!$E$5:$E$291,$A10,Data!$F$5:$F$291,"S1") -> 0 | U10: =SUMIFS(Data!$H$5:$H$291,Data!$E$5:$E$291,$A10,Data!$F$5:$F$291,"S2") -> 0 | V10: =SUMIFS(Data!$H$5:$H$291,Data!$E$5:$E$291,$A10,Data!$F$5:$F$291,"S3") -> 0 | W10: =SUMIFS(Data!$H$5:$H$291,Data!$E$5:$E$291,$A10,Data!$F$5:$F$291,"S4") -> 610 | X10: =SUMIFS(Data!$H$5:$H$291,Data!$E$5:$E$291,$A10,Data!$F$5:$F$291,"S5") -> 0 | Y10: =SUMIFS(Data!$H$5:$H$291,Data!$E$5:$E$291,$A10,Data!$F$5:$F$291,"S6") -> 0 | Z10: =SUMIFS(Data!$H$5:$H$291,Data!$E$5:$E$291,$A10,Data!$F$5:$F$291,"S7") -> 0 | AA10: =M10+N10+O10 -> 0 | AB10: =P10+Q10 -> 142939.12 | AC10: =R10+S10 -> 0 | AD10: =M10+N10+O10+P10+Q10 -> 142939.12 | AE10: =M10+N10+O10+P10+Q10+R10+S10 -> 142939.12
